<mujoco model="MIMo">
	<body childclass="a_mimo" name="a_hip" pos="0 0 0.001">
		<site name="a_lowerBody_center" type="sphere" size=".01 .01 .01" pos="0 0 0.000" />
		<geom name="a_lb" type="capsule" size="0.11 0.07" mass="7.8365" material="pants_down" pos="0 0 0" euler="90 0 0" />
		<body name="a_lower_body" pos="0 0 0.15750000000000003">
			<joint name="robot:a_hip_lean1" type="hinge" pos="0 0 -0.111" axis="0 -1 0" range="-14 14" stiffness="3.38" damping="0.77" frictionloss=".049" armature="0.01" />
			<joint name="robot:a_hip_rot1" type="hinge" pos="0 0 -0.111" axis="1 0 0" range="-18 18" stiffness="1.45" damping="0.29" frictionloss=".018" armature="0.01" />
			<joint name="robot:a_hip_bend1" type="hinge" pos="0 0 -0.111" axis="0 0 1" range="-17 30.5" stiffness="2.20" damping="0.84" frictionloss="0.040" armature="0.01" />
			<site name="a_torque_lb" type="sphere" size="0.01" pos="0 0 0.000" group="4" />
			<geom name="a_cb" type="capsule" size="0.095 0.045" mass="7.448" material="pants_up" contype="0" pos="0 0 0" euler="90 0 0" />
			<body name="a_upper_body" pos="0 0 0.1325">
				<joint name="robot:a_hip_lean2" type="hinge" pos="0 0 -0.111" axis="0 -1 0" range="-27 27" stiffness="1.69" damping="0.38" frictionloss=".024" armature="0.01" />
				<joint name="robot:a_hip_rot2" type="hinge" pos="0 0 -0.111" axis="1 0 0" range="-18 18" stiffness="1.45" damping="0.29" frictionloss=".018" armature="0.01" />
				<joint name="robot:a_hip_bend2" type="hinge" pos="0 0 -0.111" axis="0 0 1" range="-17 30.5" stiffness="2.20" damping="0.84" frictionloss="0.040" armature="0.01" />
				<site name="a_torque_ub" type="sphere" size="0.01" pos="0 0 0.000" group="4" />
				<geom name="a_ub1" type="capsule" size="0.085 0.0625" mass="8.568000000000001" material="top_down" pos="0 0 0" euler="90 0 0" />
				<geom name="a_ub2" type="capsule" size="0.075 0.075" mass="6.807999999999999" material="top_middle" pos="0 0 0.11250000000000002" euler="90 0 0" />
				<geom name="a_uni_boob" type="capsule" material="boob" size="0.045 0.075" mass="0" pos="0.075 0 0.049999999999999975" euler="90 0 0" />
				<geom name="a_left_boob" type="sphere" material="boob" size="0.05" mass="0" pos="0.075 0.07500000000000001 0.049999999999999975" />
				<geom name="a_right_boob" type="sphere" material="boob" size="0.05" mass="0" pos="0.075 -0.07500000000000001 0.049999999999999975" />
				<body name="a_neck" pos="0 0 0.22500000000000006">
					<geom name="a_neck" type="capsule" material="skin" size="0.05 0.025" mass="1.1480000000000001" pos="0 0 0.05" euler="0 0 90" />
					<site name="a_neck_center" type="sphere" size=".01 .01 .01" pos="0 0 0.000" />
					<site name="a_torque_neck" type="sphere" size="0.01" pos="0 0 0" group="4" />
					<joint name="robot:a_neck_yaw" type="hinge" pos="0 0 0" axis="0 -1 0" range="-27 27" stiffness="1.69" damping="0.38" frictionloss=".024" armature="0.01" />
					<joint name="robot:a_neck_pitch" type="hinge" pos="0 0 0" axis="1 0 0" range="-18 18" stiffness="1.45" damping="0.29" frictionloss=".018" armature="0.01" />
					<joint name="robot:a_neck_roll" type="hinge" pos="0 0 0" axis="0 0 1" range="-17 30.5" stiffness="2.20" damping="0.84" frictionloss="0.040" armature="0.01" />
					<body name="a_head" pos="0 0 0.05">
						<geom name="a_head" type="sphere" material="a_head_down" size="0.08" mass="2.2960000000000003" pos="0 0 0.08" />
						<geom name="a_headtop" type="sphere" material="a_head_up" size="0.1" mass="2.2960000000000003" pos="-0.01 0 0.125" />
						<site name="a_vestibular" type="sphere" size="0.01" pos="0.01 0 0.0735" group="4" />
						<joint name="robot:a_head_swivel" type="hinge" pos="0 0 0" axis="0 -1 0" range="-111 111" stiffness=".23" damping=".29" frictionloss=".018" armature="0.005" />
						<joint name="robot:a_head_tilt" type="hinge" pos="0 0 0.0123" axis="1 0 0" range="-70 81" stiffness=".45" damping=".53" frictionloss=".018" armature="0.005" />
						<joint name="robot:a_head_tilt_side" type="hinge" pos="0 0 0.0245" axis="0 0 1" range="-70 70" stiffness=".37" damping=".29" frictionloss=".018" armature="0.005" />
						<body name="a_left_eye" pos=".075 .024 .099" euler="0 10 0">
							<site name="a_torque_left_eye" type="sphere" size="0.01" pos="0 0 0" group="4" />
							<joint name="robot:a_left_eye_horizontal" type="hinge" pos="0 0 0" axis="0 0 1" range="-45 45" stiffness=".00065" damping=".00042" frictionloss=".000054" armature=".0002" />
							<joint name="robot:a_left_eye_vertical" type="hinge" pos="0 0 0" axis="0 -1 0" range="-47 33" stiffness=".00065" damping=".00042" frictionloss=".000054" armature=".0002" />
							<joint name="robot:a_left_eye_torsional" type="hinge" pos="0 0 0" axis="-1 0 0" range="-8 8" stiffness=".00267" damping=".00042" frictionloss=".000037" armature=".0002" />
							<geom type="sphere" material="eye_left" size=".0115" mass="0.006329" pos="0 0 0" />
							<camera name="a_eye_left" mode="fixed" fovy="60" pos="0.0115 0 0" euler="90 -90 0" />
						</body>
						<body name="a_right_eye" pos=".075 -.024 .099" euler="0 10 0">
							<site name="a_torque_right_eye" type="sphere" size="0.01" pos="0 0 0" group="4" />
							<joint name="robot:a_right_eye_horizontal" type="hinge" pos="0 0 0" axis="0 0 -1" range="-45 45" stiffness=".00065" damping=".00042" frictionloss=".000054" armature=".0002" />
							<joint name="robot:a_right_eye_vertical" type="hinge" pos="0 0 0" axis="0 -1 0" range="-47 33" stiffness=".00065" damping=".00042" frictionloss=".000054" armature=".0002" />
							<joint name="robot:a_right_eye_torsional" type="hinge" pos="0 0 0" axis="1 0 0" range="-8 8" stiffness=".00267" damping=".00042" frictionloss=".000037" armature=".0002" />
							<geom type="sphere" material="eye_right" size=".0115" mass="0.006329" pos="0 0 0" />
							<camera name="a_eye_right" mode="fixed" fovy="60" pos="0.0115 0 0" euler="90 -90 0" />
						</body>
					</body>
				</body>
				<body name="a_right_shoulder_help" pos="0 0 0.19500000000000003" euler="0 0 0">
					<joint name="robot:a_right_shoulder_x" type="hinge" pos="0 0 0" axis="0 -1 0" range="-28 118" stiffness=".09" damping=".05" frictionloss=".0009" armature="0.004" />
					<joint name="robot:a_right_shoulder_y" type="hinge" pos="0 0 0" axis="1 0 0" range="-99 67" stiffness=".12" damping=".07" frictionloss=".0008" armature="0.004" />
					<joint name="robot:a_right_shoulder_z" type="hinge" pos="0 0 0" axis="0 0 1" range="-84 183" stiffness=".11" damping=".10" frictionloss=".0014" armature="0.004" />
					<site name="a_torque_right_shoulder_helper" type="sphere" size="0.01" pos="0 0 0" group="4" />
					<geom name="a_right_shoulder_helper" type="capsule" size="0.055 0.0425" mass="2.5529999999999995" material="top_up" pos="0 -0.0425 0" euler="90 0 0" />
					<body name="a_right_upper_arm" pos="0 -0.18000000000000002 0" euler="170 90 90">
						<joint name="robot:a_right_shoulder_yaw" type="hinge" pos="0 0 0" axis="0 0 1" range="-28 118" stiffness=".09" damping=".05" frictionloss=".0009" armature="0.004" />
						<joint name="robot:a_right_shoulder_pitch" type="hinge" pos="0 0 0" axis="1 0 0" range="-84 183" stiffness=".11" damping=".10" frictionloss=".0014" armature="0.004" />
						<joint name="robot:a_right_shoulder_roll" type="hinge" pos="0 0 0" axis="0 1 0" range="-99 67" stiffness=".12" damping=".07" frictionloss=".0008" armature="0.004" />
						<site name="a_torque_right_shoulder" type="sphere" size="0.01" pos="0 0 0" group="4" />
						<geom name="a_right_uarm1" type="capsule" material="top_sleeve" size="0.04 0.1475" mass="2.03" pos="0 0 0.1475" euler="0 0 0" />
						<body name="a_right_lower_arm" pos="0 0 0.295" euler="0 0 0">
							<joint name="robot:a_right_elbow_x" type="hinge" pos="0 0 0" axis="0 0 1" springref="-20" range="-146 5" stiffness=".13" damping=".11" frictionloss=".030" armature="0.002" />
							<joint name="robot:a_right_elbow_y" type="hinge" pos="0 0 0" axis="1 0 0" springref="-20" range="-146 5" stiffness=".13" damping=".11" frictionloss=".030" armature="0.002" />
							<joint name="robot:a_right_elbow_z" type="hinge" pos="0 0 0" axis="0 1 0" springref="-20" range="-146 5" stiffness=".13" damping=".11" frictionloss=".030" armature="0.002" />
							<site name="a_torque_right_elbow" type="sphere" size="0.01" pos="0 0 0" group="4" />
							<geom name="a_right_larm" type="capsule" size="0.03 0.118" mass="1.099" pos="0 0 0.118" contype="8" conaffinity="7" />
							<body name="a_right_hand" pos="0.008 0 0.266" euler="0 0 0">
								<site name="BODY_25:a_RWrist" type="sphere" size=".005 .005 .005" pos="0 0 0" rgba="0 0 0 1" />
								<joint name="robot:a_right_hand1" type="hinge" pos="0 .007 0" axis="0 0 -1" springref="-20" range="-90 90" stiffness=".22" damping=".03" frictionloss=".007" armature="0.001" />
								<joint name="robot:a_right_hand2" type="hinge" pos="0 0 0" axis="-1 0 0" range="-92 86" stiffness=".33" damping=".11" frictionloss=".007" armature="0.001" />
								<joint name="robot:a_right_hand3" type="hinge" pos="0 0 0" axis="0 1 0" range="-53 48" stiffness=".38" damping=".11" frictionloss=".007" armature="0.001" />
								<site name="a_torque_right_wrist" type="sphere" size="0.01" pos="0 0 0" group="4" />
								<geom name="a_right_hand1" type="box" size="0.04 0.0125 0.0325" mass="0.175" pos="0 0 0.0325" />
								<geom name="a_right_hand2" type="cylinder" size="0.0125 0.04" mass="0" pos="0 0 0.065" euler="0 90 0" />
								<body name="a_right_fingers" pos="-0.0025000000000000022 0 0.065">
									<joint name="robot:a_right_fingers" type="hinge" pos="0 0 0" axis="-1 0 0" springref="-40" range="-160 8" stiffness=".017" damping=".018" frictionloss=".0023" armature="0.0001" />
									<site name="a_torque_right_fingers" type="sphere" size="0.01" pos="0 0 0" group="4" />
									<geom name="a_right_fingers1" type="box" size="0.0375 0.0125 0.030000000000000002" mass="0.175" pos="0 0 0.030000000000000002" friction="5 0.02 0.01" />
									<geom name="a_right_fingers2" type="cylinder" size="0.0125 0.0375" mass="0" pos="0 0 0.060000000000000005" euler="0 90 0" friction="5 0.02 0.01" />
								</body>
							</body>
						</body>
					</body>
				</body>
				<body name="a_left_shoulder_help" pos="0 0 0.19500000000000003" euler="0 0 0">
					<joint name="robot:a_left_shoulder_x" type="hinge" pos="0 0 0" axis="0 -1 0" range="-28 118" stiffness=".09" damping=".05" frictionloss=".0009" armature="0.004" />
					<joint name="robot:a_left_shoulder_y" type="hinge" pos="0 0 0" axis="1 0 0" range="-84 183" stiffness=".11" damping=".10" frictionloss=".0014" armature="0.004" />
					<joint name="robot:a_left_shoulder_z" type="hinge" pos="0 0 0" axis="0 0 1" range="-99 67" stiffness=".12" damping=".07" frictionloss=".0008" armature="0.004" />
					<site name="a_torque_left_shoulder_helper" type="sphere" size="0.01" pos="0 0 0" group="4" />
					<geom name="a_left_shoulder_helper" type="capsule" size="0.055 0.0425" mass="2.5529999999999995" material="top_up" pos="0 0.0425 0" euler="90 0 0" />
					<body name="a_left_upper_arm" pos="0 0.18000000000000002 0" euler="-170 90 -90">
						<joint name="robot:a_left_shoulder_yaw" type="hinge" pos="0 0 0" axis="0 0 -1" range="-28 118" stiffness=".09" damping=".05" frictionloss=".0009" armature="0.004" />
						<joint name="robot:a_left_shoulder_pitch" type="hinge" pos="0 0 0" axis="1 0 0" range="-84 183" stiffness=".11" damping=".10" frictionloss=".0014" armature="0.004" />
						<joint name="robot:a_left_shoulder_roll" type="hinge" pos="0 0 0" axis="0 -1 0" range="-99 67" stiffness=".12" damping=".07" frictionloss=".0008" armature="0.004" />
						<site name="a_torque_left_shoulder" type="sphere" size="0.01" pos="0 0 0" group="4" />
						<geom name="a_left_uarm1" type="capsule" material="top_sleeve" size="0.04 0.1475" mass="2.03" pos="0 0 0.1475" euler="0 0 0" />
						<body name="a_left_lower_arm" pos="0 0 0.295" euler="0 0 0">
							<joint name="robot:a_left_elbow_x" type="hinge" pos="0 0 0" axis="0 0 -1" springref="-20" range="-146 5" stiffness=".13" damping=".11" frictionloss=".030" armature="0.002" />
							<joint name="robot:a_left_elbow_y" type="hinge" pos="0 0 0" axis="1 0 0" springref="-20" range="-146 5" stiffness=".13" damping=".11" frictionloss=".030" armature="0.002" />
							<joint name="robot:a_left_elbow_z" type="hinge" pos="0 0 0" axis="0 -1 0" springref="-20" range="-146 5" stiffness=".13" damping=".11" frictionloss=".030" armature="0.002" />
							<site name="a_torque_left_elbow" type="sphere" size="0.01" pos="0 0 0" group="4" />
							<geom name="a_left_larm" type="capsule" size="0.03 0.118" mass="1.099" pos="0 0 0.118" contype="2" conaffinity="25" />
							<body name="a_left_hand" pos="0.008 0 0.266" euler="0 0 0">
								<site name="BODY_25:a_LWrist" type="sphere" size=".005 .005 .005" pos="0 0 0" rgba="0 0 0 1" />
								<joint name="robot:a_left_hand1" type="hinge" pos="0 .007 0" axis="0 0 1" springref="-20" range="-90 90" stiffness=".22" damping=".03" frictionloss=".007" armature="0.001" />
								<joint name="robot:a_left_hand2" type="hinge" pos="0 0 0" axis="1 0 0" range="-92 86" stiffness=".33" damping=".11" frictionloss=".007" armature="0.001" />
								<joint name="robot:a_left_hand3" type="hinge" pos="0 0 0" axis="0 1 0" range="-53 48" stiffness=".38" damping=".11" frictionloss=".007" armature="0.001" />
								<site name="a_torque_left_wrist" type="sphere" size="0.01" pos="0 0 0" group="4" />
								<geom name="a_left_hand1" type="box" size="0.04 0.0125 0.0325" mass="0.175" pos="0 0 0.0325" />
								<geom name="a_left_hand2" type="cylinder" size="0.0125 0.04" mass="0" pos="0 0 0.065" euler="0 90 0" />
								<body name="a_left_fingers" pos="-0.0025000000000000022 0 0.065">
									<joint name="robot:a_left_fingers" type="hinge" pos="0 0 0" axis="1 0 0" springref="-40" range="-160 8" stiffness=".017" damping=".018" frictionloss=".0023" armature="0.0001" />
									<site name="a_torque_left_fingers" type="sphere" size="0.01" pos="0 0 0" group="4" />
									<geom name="a_left_fingers1" type="box" size="0.0375 0.0125 0.030000000000000002" mass="0.175" pos="0 0 0.030000000000000002" friction="5 0.02 0.01" />
									<geom name="a_left_fingers2" type="cylinder" size="0.0125 0.0375" mass="0" pos="0 0 0.060000000000000005" euler="0 90 0" friction="5 0.02 0.01" />
								</body>
							</body>
						</body>
					</body>
				</body>
			</body>
		</body>
		<body name="a_right_upper_leg" pos="0 -0.095 -0.039999999999999994" euler="0 0 0">
			<joint name="robot:a_right_hip1" type="hinge" pos="0 0 0" axis="0 -1 0" springref="-10" range="-133 20" stiffness="1.72" damping="1.27" frictionloss=".08" armature=".005" />
			<joint name="robot:a_right_hip2" type="hinge" pos="0 0 0" axis="1 0 0" range="-51 17" stiffness="3.51" damping="1.99" frictionloss=".062" armature=".005" />
			<joint name="robot:a_right_hip3" type="hinge" pos="0 0 0" axis="0 0 1" range="-32 41" stiffness="2.16" damping="0.75" frictionloss=".027" armature=".005" />
			<site name="a_torque_right_hip" type="sphere" size="0.01" pos="0 0 0" group="4" />
			<geom name="a_right_uleg" type="capsule" material="pants_down" contype="2" conaffinity="3" size="0.085 0.215" mass="6.168749999999999" pos="0 0 -0.215" euler="0 0 0" />
			<body name="a_right_lower_leg" pos="0 0 -0.43">
				<joint name="robot:a_right_knee1" type="hinge" pos="0 0 0" axis="0 -1 0" springref="-30" range="-145 4" stiffness="1.63" damping="0.53" frictionloss=".065" armature=".003" />
				<joint name="robot:a_right_knee2" type="hinge" pos="0 0 0" axis="1 0 0" springref="-30" range="-145 4" stiffness="1.63" damping="0.53" frictionloss=".065" armature=".003" />
				<joint name="robot:a_right_knee3" type="hinge" pos="0 0 0" axis="0 0 1" springref="-30" range="-145 4" stiffness="1.63" damping="0.53" frictionloss=".065" armature=".003" />
				<site name="a_torque_right_knee" type="sphere" size="0.01" pos="0 0 0" group="4" />
				<geom name="a_right_lleg" type="capsule" material="pants_leg" size="0.05 0.205" mass="3.745" pos="0 0 -0.205" />
				<body name="a_right_foot" pos="0 0 -0.45999999999999996">
					<joint name="robot:a_right_foot1" type="hinge" pos="0 0 .015" axis="0 -1 0" springref="-10" range="-63 32" stiffness="1.29" damping="0.6" frictionloss=".019" armature=".003" />
					<joint name="robot:a_right_foot2" type="hinge" pos="0 0 .015" axis="-1 0 0" range="-33 31" stiffness="0.96" damping="0.37" frictionloss=".011" armature=".0025" />
					<joint name="robot:a_right_foot3" type="hinge" pos="0 0 .015" axis="0 0 -1" range="-20 30" stiffness="1.15" damping="0.38" frictionloss=".012" armature=".002" />
					<site name="a_torque_right_ankle" type="sphere" size="0.01" pos="0 0 0" group="4" />
					<site name="BODY_25:a_RAnkle" type="sphere" size=".005" pos="0 0 0.015" rgba="0 0 0 1" />
					<site name="BODY_25:a_RHeel" type="sphere" size=".005" pos="-0.02 0 0" rgba="0 0 0 1" />
					<geom name="a_right_foot1" type="cylinder" size="0.05 0.02" mass="0.1862" pos="0 0 0" euler="0 0 0" />
					<geom name="a_right_foot2" type="box" size="0.0475 0.05 0.02" mass="0.1862" pos="0.0475 0 0" euler="0 0 0" friction="2 0.02 0.01" />
					<geom name="a_right_foot3" type="cylinder" size="0.02 0.05" mass="0.1862" pos="0.095 0 0" euler="90 0 0" friction="2 0.02 0.01" />
					<body name="a_right_toes" pos="0.095 0 0">
						<joint name="robot:a_right_toes" type="hinge" pos="0 0 0" axis="0 -1 0" range="-60 80" frictionloss=".005" armature=".0005" stiffness=".106" damping=".04" />
						<site name="a_torque_right_toes" type="sphere" size="0.01" pos="0 0 0" group="4" />
						<geom name="a_right_toes1" type="box" size="0.017499999999999998 0.05 0.02" mass="0.1862" pos="0.017499999999999998 0 0" euler="0 0 0" friction="2 0.02 0.01" />
						<geom name="a_right_toes2" type="cylinder" size="0.02 0.05" mass="0.1862" pos="0.034999999999999996 0 0" euler="90 0 0" friction="2 0.02 0.01" />
						<site name="BODY_25:a_RBigToe" type="sphere" size=".005" pos=".011 -0.012 0" rgba="0 0 0 1" />
						<site name="BODY_25:a_RSmallToe" type="sphere" size=".005" pos=".010 0.012 0" rgba="0 0 0 1" />
					</body>
				</body>
			</body>
		</body>
		<body name="a_left_upper_leg" pos="0 0.095 -0.039999999999999994" euler="0 0 0">
			<joint name="robot:a_left_hip1" type="hinge" pos="0 0 0" axis="0 -1 0" springref="-10" range="-133 20" stiffness="1.72" damping="1.27" frictionloss=".08" armature=".005" />
			<joint name="robot:a_left_hip2" type="hinge" pos="0 0 0" axis="1 0 0" range="-51 17" stiffness="3.51" damping="1.99" frictionloss=".062" armature=".005" />
			<joint name="robot:a_left_hip3" type="hinge" pos="0 0 0" axis="0 0 1" range="-32 41" stiffness="2.16" damping="0.75" frictionloss=".027" armature=".005" />
			<site name="a_torque_left_hip" type="sphere" size="0.01" pos="0 0 0" group="4" />
			<geom name="a_left_uleg" type="capsule" material="pants_down" contype="2" conaffinity="3" size="0.085 0.215" mass="6.168749999999999" pos="0 0 -0.215" euler="0 0 0" />
			<body name="a_left_lower_leg" pos="0 0 -0.43">
				<joint name="robot:a_left_knee1" type="hinge" pos="0 0 0" axis="0 -1 0" springref="-30" range="-145 4" stiffness="1.63" damping="0.53" frictionloss=".065" armature=".003" />
				<joint name="robot:a_left_knee2" type="hinge" pos="0 0 0" axis="1 0 0" springref="-30" range="-145 4" stiffness="1.63" damping="0.53" frictionloss=".065" armature=".003" />
				<joint name="robot:a_left_knee3" type="hinge" pos="0 0 0" axis="0 0 1" springref="-30" range="-145 4" stiffness="1.63" damping="0.53" frictionloss=".065" armature=".003" />
				<site name="a_torque_left_knee" type="sphere" size="0.01" pos="0 0 0" group="4" />
				<geom name="a_left_lleg" type="capsule" material="pants_leg" size="0.05 0.205" mass="3.745" pos="0 0 -0.205" euler="0 0 0" />
				<body name="a_left_foot" pos="0 0 -0.45999999999999996">
					<joint name="robot:a_left_foot1" type="hinge" pos="0 0 .015" axis="0 -1 0" springref="-10" range="-63 32" stiffness="1.29" damping="0.6" frictionloss=".019" armature=".003" />
					<joint name="robot:a_left_foot2" type="hinge" pos="0 0 .015" axis="-1 0 0" range="-33 31" stiffness="0.96" damping="0.37" frictionloss=".011" armature=".0025" />
					<joint name="robot:a_left_foot3" type="hinge" pos="0 0 .015" axis="0 0 -1" range="-20 30" stiffness="1.15" damping="0.38" frictionloss=".012" armature=".002" />
					<site name="a_torque_left_ankle" type="sphere" size="0.01" pos="0 0 0" group="4" />
					<site name="BODY_25:a_LAnkle" type="sphere" size=".005" pos="0 0 0.015" rgba="0 0 0 1" />
					<site name="BODY_25:a_LHeel" type="sphere" size=".005" pos="-0.02 0 0" rgba="0 0 0 1" />
					<geom name="a_left_foot1" type="cylinder" size="0.05 0.02" mass="0.1862" pos="0 0 0" euler="0 0 0" />
					<geom name="a_left_foot2" type="box" size="0.0475 0.05 0.02" mass="0.1862" pos="0.0475 0 0" euler="0 0 0" friction="2 0.02 0.01" />
					<geom name="a_left_foot3" type="cylinder" size="0.02 0.05" mass="0.1862" pos="0.095 0 0" euler="90 0 0" friction="2 0.02 0.01" />
					<body name="a_left_toes" pos="0.095 0 0">
						<joint name="robot:a_left_toes" type="hinge" pos="0 0 0" axis="0 -1 0" range="-60 80" frictionloss=".005" armature=".0005" stiffness=".106" damping=".04" />
						<site name="a_torque_left_toes" type="sphere" size="0.01" pos="0 0 0" group="4" />
						<geom name="a_left_toes1" type="box" size="0.017499999999999998 0.05 0.02" mass="0.1862" pos="0.017499999999999998 0 0" euler="0 0 0" friction="2 0.02 0.01" />
						<geom name="a_left_toes2" type="cylinder" size="0.02 0.05" mass="0.1862" pos="0.034999999999999996 0 0" euler="90 0 0" friction="2 0.02 0.01" />
						<site name="BODY_25:a_LBigToe" type="sphere" size=".005" pos=".011 -0.012 0" rgba="0 0 0 1" />
						<site name="BODY_25:a_LSmallToe" type="sphere" size=".005" pos=".010 0.012 0" rgba="0 0 0 1" />
					</body>
				</body>
			</body>
		</body>
	</body>
</mujoco>