<mujoco model="MIMo">
	<body childclass="a_mimo" name="a_hip" pos="0 0 0.001">
		<geom name="a_lb" type="capsule" size="0.11 0.07" mass="7.8365" material="pants_down" pos="0 0 0" euler="90 0 0" />
		<body name="a_lower_body" pos="0 0 0.15750000000000003">
			<joint name="robot:a_hip_lean1" type="hinge" pos="0 0 -0.111" axis="0 -1 0" range="-14 14" stiffness="3.38" damping="0.77" frictionloss=".049" armature="0.01" />
			<joint name="robot:a_hip_rot1" type="hinge" pos="0 0 -0.111" axis="1 0 0" range="-18 18" stiffness="1.45" damping="0.29" frictionloss=".018" armature="0.01" />
			<joint name="robot:a_hip_bend1" type="hinge" pos="0 0 -0.111" axis="0 0 1" range="-17 30.5" stiffness="2.20" damping="0.84" frictionloss="0.040" armature="0.01" />
			<site name="a_torque_lb" type="sphere" size="0.01" pos="0 0 0.000" group="4" />
			<geom name="a_cb" type="capsule" size="0.095 0.045" mass="7.448" material="pants_up" contype="0" pos="0 0 0" euler="90 0 0" />
			<body name="a_upper_body" pos="0 0 0.1325">
				<joint name="robot:a_hip_lean2" type="hinge" pos="0 0 -0.111" axis="0 -1 0" range="-27 27" stiffness="1.69" damping="0.38" frictionloss=".024" armature="0.01" />
				<joint name="robot:a_hip_rot2" type="hinge" pos="0 0 -0.111" axis="1 0 0" range="-18 18" stiffness="1.45" damping="0.29" frictionloss=".018" armature="0.01" />
				<joint name="robot:a_hip_bend2" type="hinge" pos="0 0 -0.111" axis="0 0 1" range="-17 30.5" stiffness="2.20" damping="0.84" frictionloss="0.040" armature="0.01" />
				<site name="a_torque_ub" type="sphere" size="0.01" pos="0 0 0.000" group="4" />
				<geom name="a_ub1" type="capsule" size="0.085 0.0625" mass="8.568000000000001" material="top_down" pos="0 0 0" euler="90 0 0" />
				<geom name="a_ub2" type="capsule" size="0.075 0.075" mass="6.807999999999999" material="top_middle" pos="0 0 0.11250000000000002" euler="90 0 0" />
				<geom name="a_uni_boob" type="capsule" material="boob" size="0.045 0.075" mass="0" pos="0.075 0 0.049999999999999975" euler="90 0 0" />
				<geom name="a_left_boob" type="sphere" material="boob" size="0.05" mass="0" pos="0.075 0.07500000000000001 0.049999999999999975" />
				<geom name="a_right_boob" type="sphere" material="boob" size="0.05" mass="0" pos="0.075 -0.07500000000000001 0.049999999999999975" />
				<body name="a_neck" pos="0 0 0.22500000000000006">
					<geom name="a_neck" type="capsule" material="skin" size="0.05 0.025" mass="1.1480000000000001" pos="0 0 0.05" euler="0 0 90" />
					<site name="a_torque_neck" type="sphere" size="0.01" pos="0 0 0" group="4" />
					<joint name="robot:a_neck_yaw" type="hinge" pos="0 0 -0.02" axis="0 -1 0" range="-27 27" stiffness="1.69" damping="0.38" frictionloss=".024" armature="0.01" />
					<joint name="robot:a_neck_pitch" type="hinge" pos="0 0 -0.02" axis="1 0 0" range="-18 18" stiffness="1.45" damping="0.29" frictionloss=".018" armature="0.01" />
					<joint name="robot:a_neck_roll" type="hinge" pos="0 0 -0.02" axis="0 0 1" range="-17 30.5" stiffness="2.20" damping="0.84" frictionloss="0.040" armature="0.01" />
					<body name="a_head" pos="0 0 0.05">
						<geom name="a_head" type="sphere" material="a_head_down" size="0.08" mass="2.2960000000000003" pos="0 0 0.08" />
						<geom name="a_headtop" type="sphere" material="a_head_up" size="0.1" mass="2.2960000000000003" pos="-0.01 0 0.125" />
						<site name="a_vestibular" type="sphere" size="0.01" pos="0.01 0 0.0735" group="4" />
						<joint name="robot:a_head_swivel" type="hinge" pos="0 0 0" axis="0 -1 0" range="-111 111" stiffness=".23" damping=".29" frictionloss=".018" armature="0.005" />
						<joint name="robot:a_head_tilt" type="hinge" pos="0 0 0.0123" axis="1 0 0" range="-70 81" stiffness=".45" damping=".53" frictionloss=".018" armature="0.005" />
						<joint name="robot:a_head_tilt_side" type="hinge" pos="0 0 0.0245" axis="0 0 1" range="-70 70" stiffness=".37" damping=".29" frictionloss=".018" armature="0.005" />
						<body name="a_left_eye" pos=".075 .024 .099" euler="0 10 0">
							<site name="a_torque_left_eye" type="sphere" size="0.01" pos="0 0 0" group="4" />
							<joint name="robot:a_left_eye_horizontal" type="hinge" pos="0 0 0" axis="0 0 1" range="-45 45" stiffness=".00065" damping=".00042" frictionloss=".000054" armature=".0002" />
							<joint name="robot:a_left_eye_vertical" type="hinge" pos="0 0 0" axis="0 -1 0" range="-47 33" stiffness=".00065" damping=".00042" frictionloss=".000054" armature=".0002" />
							<joint name="robot:a_left_eye_torsional" type="hinge" pos="0 0 0" axis="-1 0 0" range="-8 8" stiffness=".00267" damping=".00042" frictionloss=".000037" armature=".0002" />
							<geom type="sphere" material="eye_left" size=".0115" mass="0.006329" pos="0 0 0" />
							<camera name="a_eye_left" mode="fixed" fovy="60" pos="0.0115 0 0" euler="90 -90 0" />
						</body>
						<body name="a_right_eye" pos=".075 -.024 .099" euler="0 10 0">
							<site name="a_torque_right_eye" type="sphere" size="0.01" pos="0 0 0" group="4" />
							<joint name="robot:a_right_eye_horizontal" type="hinge" pos="0 0 0" axis="0 0 -1" range="-45 45" stiffness=".00065" damping=".00042" frictionloss=".000054" armature=".0002" />
							<joint name="robot:a_right_eye_vertical" type="hinge" pos="0 0 0" axis="0 -1 0" range="-47 33" stiffness=".00065" damping=".00042" frictionloss=".000054" armature=".0002" />
							<joint name="robot:a_right_eye_torsional" type="hinge" pos="0 0 0" axis="1 0 0" range="-8 8" stiffness=".00267" damping=".00042" frictionloss=".000037" armature=".0002" />
							<geom type="sphere" material="eye_right" size=".0115" mass="0.006329" pos="0 0 0" />
							<camera name="a_eye_right" mode="fixed" fovy="60" pos="0.0115 0 0" euler="90 -90 0" />
						</body>
					</body>
				</body>
				<body name="a_right_shoulder_help" pos="0 0 0.19500000000000003" euler="0 0 0">
					<joint name="robot:a_right_shoulder_x" type="hinge" pos="0 0 0" axis="0 -1 0" range="-28 118" stiffness=".09" damping=".05" frictionloss=".0009" armature="0.004" />
					<joint name="robot:a_right_shoulder_y" type="hinge" pos="0 0 0" axis="1 0 0" range="-99 67" stiffness=".12" damping=".07" frictionloss=".0008" armature="0.004" />
					<joint name="robot:a_right_shoulder_z" type="hinge" pos="0 0 0" axis="0 0 1" range="-84 183" stiffness=".11" damping=".10" frictionloss=".0014" armature="0.004" />
					<site name="a_torque_right_shoulder_helper" type="sphere" size="0.01" pos="0 0 0" group="4" />
					<geom name="a_right_shoulder_helper" type="capsule" size="0.055 0.0425" mass="2.5529999999999995" material="top_up" pos="0 -0.0425 0" euler="90 0 0" />
					<body name="a_right_upper_arm" pos="0 -0.18000000000000002 0" euler="170 90 180">
						<joint name="robot:a_right_shoulder_yaw" type="hinge" pos="0 0 0" axis="1 0 0" range="-28 118" stiffness=".09" damping=".05" frictionloss=".0009" armature="0.004" />
						<joint name="robot:a_right_shoulder_pitch" type="hinge" pos="0 0 0" axis="0 -1 0" range="-84 183" stiffness=".11" damping=".10" frictionloss=".0014" armature="0.004" />
						<joint name="robot:a_right_shoulder_roll" type="hinge" pos="0 0 0" axis="0 0 -1" range="-99 67" stiffness=".12" damping=".07" frictionloss=".0008" armature="0.004" />
						<site name="a_torque_right_shoulder" type="sphere" size="0.01" pos="0 0 0" group="4" />
						<geom name="a_right_uarm1" type="capsule" material="top_sleeve" size="0.04 0.1475" mass="2.03" pos="0 0 0.1475" euler="0 0 0" />
						<body name="a_right_lower_arm" pos="0 0 0.295" euler="0 0 -90">
							<joint name="robot:a_right_elbow_x" type="hinge" pos="0 0 0" axis="1 0 0" springref="-20" range="-146 5" stiffness=".13" damping=".11" frictionloss=".030" armature="0.002" />
							<joint name="robot:a_right_elbow_y" type="hinge" pos="0 0 0" axis="0 -1 0" springref="-20" range="-146 5" stiffness=".13" damping=".11" frictionloss=".030" armature="0.002" />
							<joint name="robot:a_right_elbow_z" type="hinge" pos="0 0 0" axis="0 0 -1" springref="-20" range="-146 5" stiffness=".13" damping=".11" frictionloss=".030" armature="0.002" />
							<site name="a_torque_right_elbow" type="sphere" size="0.01" pos="0 0 0" group="4" />
							<geom name="a_right_larm" type="capsule" size="0.03 0.118" mass="1.099" pos="0 0 0.118" contype="8" conaffinity="7" />
							<body name="a_right_hand" pos="0.008 0 0.306" euler="0 0 0">
								<joint name="robot:a_right_hand1" type="hinge" pos="0.0 0.0 -0.035" axis="1 0 0" springref="-20" range="-90 90" stiffness=".22" damping=".03" frictionloss=".007" armature="0.001" />
								<joint name="robot:a_right_hand2" type="hinge" pos="0.0 0.0 -0.035" axis="0 -1 0" range="-92 86" stiffness=".33" damping=".11" frictionloss=".007" armature="0.001" />
								<joint name="robot:a_right_hand3" type="hinge" pos="0.0 0.0 -0.035" axis="0 0 -1" range="-53 48" stiffness=".38" damping=".11" frictionloss=".007" armature="0.001" />
								<site name="a_torque_right_wrist" type="sphere" size="0.0027646129541864144" pos="0.0 0.0 0.0" group="4" />
								<geom type="box" pos="0.0 0.0 0.0" size="0.023665086887835706 0.00807266982622433 0.035" mass="0.01895" condim="6" />
								<geom type="box" pos="-0.031793048973143764 0.0 -0.017140600315955767" size="0.008127962085308058 0.00807266982622433 0.017859399684044236" mass=".003321" condim="6" />
								<geom type="cylinder" pos="0.0 0.0 0.035" size="0.00807266982622433 0.023637440758293844" mass=".003367" euler="0 90 0" condim="6" />
								<geom type="cylinder" pos="-0.008127962085308058 0.0 -0.035" size="0.00807266982622433 0.0317654028436019" mass=".004524" euler="0 90 0" condim="6" />
								<body name="a_right_ffknuckle" pos="0.016269747235387048 0.0 0.040708925750394954">
									<joint name="robot:a_right_ff_side" type="hinge" pos="0.0 0.0 0.0" axis="0 1 0" range="-25 25" stiffness=".003" damping="0.001" armature="0.0001" />
									<joint name="robot:a_right_ff_knuckle" type="hinge" pos="0.0 0.0 0.0" axis="1 0 0" range="-20 90" springref="45" stiffness="0.0008" damping="0.0005" armature="0.0001" />
									<site name="a_torque_right_ff_knuckle" type="sphere" size="0.0027646129541864144" pos="0.0 0.0 0.0" group="4" />
									<geom type="capsule" pos="0.0 0.0 0.013712480252764616" size="0.007588862559241708 0.013712480252764616" mass=".002692" condim="6" />
									<body name="a_right_ffmiddle" pos="0.0 0.0 0.027438783570300163">
										<joint name="robot:a_right_ff_middle" type="hinge" pos="0.0 0.0 0.0" axis="1 0 0" range="-5 100" springref="45" stiffness="0.0006" damping="0.0005" armature="0.0001" />
										<site name="a_torque_right_ff_middle" type="sphere" size="0.0027646129541864144" pos="0.0 0.0 0.0" group="4" />
										<geom type="capsule" pos="0.0 0.0 0.011141390205371249" size="0.007187993680884677 0.006925355450236968" mass=".001497" condim="6" />
										<body name="a_right_ffdistal" pos="0.0 0.0 0.018661137440758296">
											<joint name="robot:a_right_ff_distal" type="hinge" pos="0.0 0.0 0.0" axis="1 0 0" range="-5 80" springref="30" stiffness="0.0006" damping="0.0005" armature="0.0001" />
											<site name="a_torque_right_ff_distal" type="sphere" size="0.0027646129541864144" pos="0.0 0.0 0.0" group="4" />
											<geom type="capsule" pos="0.0 0.0 0.009247630331753557" size="0.0069115323854660364 0.0064139020537124815" mass=".001291" condim="6" />
										</body>
									</body>
								</body>
								<body name="a_right_mfknuckle" pos="0.0 0.0 0.04357030015797789">
									<joint name="robot:a_right_mf_side" type="hinge" pos="0.0 0.0 0.0" axis="0 1 0" range="-25 25" stiffness=".003" damping="0.001" armature="0.0001" />
									<joint name="robot:a_right_mf_knuckle" type="hinge" pos="0.0 0.0 0.0" axis="1 0 0" range="-20 90" springref="45" stiffness="0.0010" damping="0.0005" armature="0.0001" />
									<site name="a_torque_right_mf_knuckle" type="sphere" size="0.0027646129541864144" pos="0.0 0.0 0.0" group="4" />
									<geom type="capsule" pos="0.0 0.0 0.015205371248025278" size="0.00800355450236967 0.015205371248025278" mass=".003284" condim="6" />
									<body name="a_right_mfmiddle" pos="0.0 0.0 0.030410742496050556">
										<joint name="robot:a_right_mf_middle" type="hinge" pos="0.0 0.0 0.0" axis="1 0 0" range="-5 100" springref="45" stiffness="0.0007" damping="0.0005" armature="0.0001" />
										<site name="a_torque_right_mf_middle" type="sphere" size="0.0027646129541864144" pos="0.0 0.0 0.0" group="4" />
										<geom type="capsule" pos="0.0 0.0 0.011984597156398108" size="0.007464454976303319 0.007768562401263825" mass=".001757" condim="6" />
										<body name="a_right_mfdistal" pos="0.0 0.0 0.020043443917851504">
											<joint name="robot:a_right_mf_distal" type="hinge" pos="0.0 0.0 0.0" axis="1 0 0" range="-5 80" springref="30" stiffness="0.0006" damping="0.0005" armature="0.0001" />
											<site name="a_torque_right_mf_distal" type="sphere" size="0.0027646129541864144" pos="0.0 0.0 0.0" group="4" />
											<geom type="capsule" pos="0.0 0.0 0.010256714060031598" size="0.007187993680884677 0.007436808846761455" mass=".001563" condim="6" />
										</body>
									</body>
								</body>
								<body name="a_right_rfknuckle" pos="-0.016269747235387048 0.0 0.040708925750394954">
									<joint name="robot:a_right_rf_side" type="hinge" pos="0.0 0.0 0.0" axis="0 1 0" range="-25 25" stiffness=".003" damping="0.001" armature="0.0001" />
									<joint name="robot:a_right_rf_knuckle" type="hinge" pos="0.0 0.0 0.0" axis="1 0 0" range="-20 90" springref="45" stiffness="0.0009" damping="0.0005" armature="0.0001" />
									<site name="a_torque_right_rf_knuckle" type="sphere" size="0.0027646129541864144" pos="0.0 0.0 0.0" group="4" />
									<geom type="capsule" pos="0.0 0.0 0.013518957345971567" size="0.007588862559241708 0.013518957345971567" mass=".002664" condim="6" />
									<body name="a_right_rfmiddle" pos="0.0 0.0 0.027037914691943134">
										<joint name="robot:a_right_rf_middle" type="hinge" pos="0.0 0.0 0.0" axis="1 0 0" range="-5 100" springref="45" stiffness="0.0007" damping="0.0005" armature="0.0001" />
										<site name="a_torque_right_rf_middle" type="sphere" size="0.0027646129541864144" pos="0.0 0.0 0.0" group="4" />
										<geom type="capsule" pos="0.0 0.0 0.010961690363349132" size="0.007187993680884677 0.006759478672985784" mass=".001476" condim="6" />
										<body name="a_right_rfdistal" pos="0.0 0.0 0.017969984202211693">
											<joint name="robot:a_right_rf_distal" type="hinge" pos="0.0 0.0 0.0" axis="1 0 0" range="-5 80" springref="30" stiffness="0.0006" damping="0.0005" armature="0.0001" />
											<site name="a_torque_right_rf_distal" type="sphere" size="0.0027646129541864144" pos="0.0 0.0 0.0" group="4" />
											<geom type="capsule" pos="0.0 0.0 0.009454976303317536" size="0.0069115323854660364 0.006621248025276462" mass=".001316" condim="6" />
										</body>
									</body>
								</body>
								<body name="a_right_lfmetacarpal" pos="-0.020706951026856244 0.0 0.004285150078988942">
									<joint name="robot:a_right_lf_meta" type="hinge" pos="0.0 0.0 0.0" axis="0.571 0 0.821" range="0 40" stiffness=".01" damping=".001" armature="0.0001" />
									<site name="a_torque_right_lf_meta" type="sphere" size="0.0027646129541864144" pos="0.0 0.0 0.0" group="4" />
									<geom type="box" pos="-0.012205766192733019 0.0 0.007146524486571881" size="0.007022116903633493 0.00807266982622433 0.017859399684044236" mass=".002879" condim="6" contype="16" conaffinity="7" />
									<geom type="cylinder" pos="-0.012205766192733019 0.0 0.025005924170616117" size="0.00807266982622433 0.0069115323854660364" mass=".0009879" euler="0 90 0" condim="6" contype="16" conaffinity="7" />
									<body name="a_right_lfknuckle" pos="-0.011735781990521329 0.0 0.0314198262243286">
										<joint name="robot:a_right_lf_side" type="hinge" pos="0.0 0.0 0.0" axis="0 1 0" range="-25 25" stiffness="0.003" damping="0.001" armature="0.0001" />
										<joint name="robot:a_right_lf_knuckle" type="hinge" pos="0.0 0.0 0.0" axis="1 0 0" range="-20 90" springref="45" stiffness="0.0007" damping="0.0005" armature="0.0001" />
										<site name="a_torque_right_lf_knuckle" type="sphere" size="0.0027646129541864144" pos="0.0 0.0 0.0" group="4" />
										<geom type="capsule" pos="0.0 0.0 0.011279620853080572" size="0.007312401263823066 0.011279620853080572" mass=".002143" condim="6" />
										<body name="a_right_lfmiddle" pos="0.0 0.0 0.02294628751974724">
											<joint name="robot:a_right_lf_middle" type="hinge" pos="0.0 0.0 0.0" axis="1 0 0" range="-5 100" springref="45" stiffness="0.0006" damping="0.0005" armature="0.0001" />
											<site name="a_torque_right_lf_middle" type="sphere" size="0.0027646129541864144" pos="0.0 0.0 0.0" group="4" />
											<geom type="capsule" pos="0.0 0.0 0.0069115323854660364" size="0.0069115323854660364 0.006289494470774093" mass=".001276" condim="6" />
											<body name="a_right_lfdistal" pos="0.0 0.0 0.012717219589257506">
												<joint name="robot:a_right_lf_distal" type="hinge" pos="0.0 0.0 0.0" axis="1 0 0" range="-5 80" springref="30" stiffness="0.0006" damping="0.0005" armature="0.0001" />
												<site name="a_torque_right_lf_distal" type="sphere" size="0.0027646129541864144" pos="0.0 0.0 0.0" group="4" />
												<geom type="capsule" pos="0.0 0.0 0.008238546603475515" size="0.006773301737756715 0.00540481832543444" mass=".001113" condim="6" />
											</body>
										</body>
									</body>
								</body>
								<body name="a_right_thbase" pos="0.017002369668246448 -0.005847156398104267 -0.022144549763033178" euler="0 80 30">
									<joint name="robot:a_right_th_swivel" type="hinge" pos="0.0 0.0 0.0" axis="3 -5 -1" range="-10 110" springref="40" stiffness="0.003" damping="0.001" armature="0.0001" />
									<joint name="robot:a_right_th_adduction" type="hinge" pos="0.0 0.0 0.0" axis="1 2 0" range="-60 0" springref="-35" stiffness="0.004" damping="0.001" armature="0.0001" />
									<site name="a_torque_right_th_base" type="sphere" size="0.0027646129541864144" pos="0.0 0.0 0.0" group="4" />
									<geom type="capsule" pos="0.0 0.0 0.014196287519747237" size="0.010173775671406005 0.014196287519747237" mass=".005463" condim="6" contype="16" conaffinity="7" />
									<body name="a_right_thhub" pos="0.0 0.0 0.029374012638230654">
										<joint name="robot:a_right_th_pivot" type="hinge" pos="0.0 0.0 0.0" axis="1 0 0" range="-10 10" springref="0" stiffness="0.002" damping="0.001" armature="0.0001" />
										<joint name="robot:a_right_th_middle" type="hinge" pos="0.0 0.0 0.0" axis="0 -1 0" range="0 90" springref="30" stiffness="0.004" damping="0.001" armature="0.0001" />
										<site name="a_torque_right_th_hub" type="sphere" size="0.0027646129541864144" pos="0.0 0.0 0.0" group="4" />
										<geom type="capsule" pos="0.0 0.0 0.011749605055292262" size="0.008819115323854662 0.009634676145339654" mass=".003021" condim="6" />
										<body name="a_right_thdistal" pos="0.0 0.0 0.020734597156398107">
											<joint name="robot:a_right_th_distal" type="hinge" pos="0.0 0.0 0.0" axis="0 -1 0" range="0 90" springref="20" stiffness="0.004" damping="0.001" armature="0.0001" />
											<site name="a_torque_right_th_distal" type="sphere" size="0.0027646129541864144" pos="0.0 0.0 0.0" group="4" />
											<geom type="capsule" pos="0.0 0.0 0.013767772511848344" size="0.00854265402843602 0.008114139020537127" mass=".002509" condim="6" />
										</body>
									</body>
								</body>
							</body>
						</body>
					</body>
				</body>
				<body name="a_left_shoulder_help" pos="0 0 0.19500000000000003" euler="0 0 0">
					<joint name="robot:a_left_shoulder_x" type="hinge" pos="0 0 0" axis="0 -1 0" range="-28 118" stiffness=".09" damping=".05" frictionloss=".0009" armature="0.004" />
					<joint name="robot:a_left_shoulder_y" type="hinge" pos="0 0 0" axis="1 0 0" range="-84 183" stiffness=".11" damping=".10" frictionloss=".0014" armature="0.004" />
					<joint name="robot:a_left_shoulder_z" type="hinge" pos="0 0 0" axis="0 0 1" range="-99 67" stiffness=".12" damping=".07" frictionloss=".0008" armature="0.004" />
					<site name="a_torque_left_shoulder_helper" type="sphere" size="0.01" pos="0 0 0" group="4" />
					<geom name="a_left_shoulder_helper" type="capsule" size="0.055 0.0425" mass="2.5529999999999995" material="top_up" pos="0 0.0425 0" euler="90 0 0" />
					<body name="a_left_upper_arm" pos="0 0.18000000000000002 0" euler="-170 90 -180">
						<joint name="robot:a_left_shoulder_yaw" type="hinge" pos="0 0 0" axis="-1 0 0" range="-28 118" stiffness=".09" damping=".05" frictionloss=".0009" armature="0.004" />
						<joint name="robot:a_left_shoulder_pitch" type="hinge" pos="0 0 0" axis="0 1 0" range="-84 183" stiffness=".11" damping=".10" frictionloss=".0014" armature="0.004" />
						<joint name="robot:a_left_shoulder_roll" type="hinge" pos="0 0 0" axis="0 0 -1" range="-99 67" stiffness=".12" damping=".07" frictionloss=".0008" armature="0.004" />
						<site name="a_torque_left_shoulder" type="sphere" size="0.01" pos="0 0 0" group="4" />
						<geom name="a_left_uarm1" type="capsule" material="top_sleeve" size="0.04 0.1475" mass="2.03" pos="0 0 0.1475" euler="0 0 0" />
						<body name="a_left_lower_arm" pos="0 0 0.295" euler="0 0 90">
							<joint name="robot:a_left_elbow_x" type="hinge" pos="0 0 0" axis="-1 0 0" springref="-20" range="-146 5" stiffness=".13" damping=".11" frictionloss=".030" armature="0.002" />
							<joint name="robot:a_left_elbow_y" type="hinge" pos="0 0 0" axis="0 1 0" springref="-20" range="-146 5" stiffness=".13" damping=".11" frictionloss=".030" armature="0.002" />
							<joint name="robot:a_left_elbow_z" type="hinge" pos="0 0 0" axis="0 0 -1" springref="-20" range="-146 5" stiffness=".13" damping=".11" frictionloss=".030" armature="0.002" />
							<site name="a_torque_left_elbow" type="sphere" size="0.01" pos="0 0 0" group="4" />
							<geom name="a_left_larm" type="capsule" size="0.03 0.118" mass="1.099" pos="0 0 0.118" contype="2" conaffinity="25" />
							<body name="a_left_hand" pos="0.008 0 0.306" euler="0 0 0">
								<joint name="robot:a_left_hand1" type="hinge" pos="0.0 0.0 -0.035" axis="-1 0 0" springref="-20" range="-90 90" stiffness=".22" damping=".03" frictionloss=".007" armature="0.001" />
								<joint name="robot:a_left_hand2" type="hinge" pos="0.0 0.0 -0.035" axis="0 1 0" range="-92 86" stiffness=".33" damping=".11" frictionloss=".007" armature="0.001" />
								<joint name="robot:a_left_hand3" type="hinge" pos="0.0 0.0 -0.035" axis="0 0 -1" range="-53 48" stiffness=".38" damping=".11" frictionloss=".007" armature="0.001" />
								<site name="a_torque_left_wrist" type="sphere" size="0.0027646129541864144" pos="0.0 0.0 0.0" group="4" />
								<geom type="box" pos="0.0 0.0 0.0" size="0.023665086887835706 0.00807266982622433 0.035" mass="0.01895" condim="6" />
								<geom type="box" pos="-0.031793048973143764 0.0 -0.017140600315955767" size="0.008127962085308058 0.00807266982622433 0.017859399684044236" mass=".003321" condim="6" />
								<geom type="cylinder" pos="0.0 0.0 0.035" size="0.00807266982622433 0.023637440758293844" mass=".003367" euler="0 90 0" condim="6" />
								<geom type="cylinder" pos="-0.008127962085308058 0.0 -0.035" size="0.00807266982622433 0.0317654028436019" mass=".004524" euler="0 90 0" condim="6" />
								<body name="a_left_ffknuckle" pos="0.016269747235387048 0.0 0.040708925750394954">
									<joint name="robot:a_left_ff_side" type="hinge" pos="0.0 0.0 0.0" axis="0 1 0" range="-25 25" stiffness=".003" damping="0.001" armature="0.0001" />
									<joint name="robot:a_left_ff_knuckle" type="hinge" pos="0.0 0.0 0.0" axis="-1 0 0" range="-20 90" springref="45" stiffness="0.0008" damping="0.0005" armature="0.0001" />
									<site name="a_torque_left_ff_knuckle" type="sphere" size="0.0027646129541864144" pos="0.0 0.0 0.0" group="4" />
									<geom type="capsule" pos="0.0 0.0 0.013712480252764616" size="0.007588862559241708 0.013712480252764616" mass=".002692" condim="6" />
									<body name="a_left_ffmiddle" pos="0.0 0.0 0.027438783570300163">
										<joint name="robot:a_left_ff_middle" type="hinge" pos="0.0 0.0 0.0" axis="-1 0 0" range="-5 100" springref="45" stiffness="0.0006" damping="0.0005" armature="0.0001" />
										<site name="a_torque_left_ff_middle" type="sphere" size="0.0027646129541864144" pos="0.0 0.0 0.0" group="4" />
										<geom type="capsule" pos="0.0 0.0 0.011141390205371249" size="0.007187993680884677 0.006925355450236968" mass=".001497" condim="6" />
										<body name="a_left_ffdistal" pos="0.0 0.0 0.018661137440758296">
											<joint name="robot:a_left_ff_distal" type="hinge" pos="0.0 0.0 0.0" axis="-1 0 0" range="-5 80" springref="30" stiffness="0.0006" damping="0.0005" armature="0.0001" />
											<site name="a_torque_left_ff_distal" type="sphere" size="0.0027646129541864144" pos="0.0 0.0 0.0" group="4" />
											<geom type="capsule" pos="0.0 0.0 0.009247630331753557" size="0.0069115323854660364 0.0064139020537124815" mass=".001291" condim="6" />
										</body>
									</body>
								</body>
								<body name="a_left_mfknuckle" pos="0.0 0.0 0.04357030015797789">
									<joint name="robot:a_left_mf_side" type="hinge" pos="0.0 0.0 0.0" axis="0 1 0" range="-25 25" stiffness=".003" damping="0.001" armature="0.0001" />
									<joint name="robot:a_left_mf_knuckle" type="hinge" pos="0.0 0.0 0.0" axis="-1 0 0" range="-20 90" springref="45" stiffness="0.0010" damping="0.0005" armature="0.0001" />
									<site name="a_torque_left_mf_knuckle" type="sphere" size="0.0027646129541864144" pos="0.0 0.0 0.0" group="4" />
									<geom type="capsule" pos="0.0 0.0 0.015205371248025278" size="0.00800355450236967 0.015205371248025278" mass=".003284" condim="6" />
									<body name="a_left_mfmiddle" pos="0.0 0.0 0.030410742496050556">
										<joint name="robot:a_left_mf_middle" type="hinge" pos="0.0 0.0 0.0" axis="-1 0 0" range="-5 100" springref="45" stiffness="0.0007" damping="0.0005" armature="0.0001" />
										<site name="a_torque_left_mf_middle" type="sphere" size="0.0027646129541864144" pos="0.0 0.0 0.0" group="4" />
										<geom type="capsule" pos="0.0 0.0 0.011984597156398108" size="0.007464454976303319 0.007768562401263825" mass=".001757" condim="6" />
										<body name="a_left_mfdistal" pos="0.0 0.0 0.020043443917851504">
											<joint name="robot:a_left_mf_distal" type="hinge" pos="0.0 0.0 0.0" axis="-1 0 0" range="-5 80" springref="30" stiffness="0.0006" damping="0.0005" armature="0.0001" />
											<site name="a_torque_left_mf_distal" type="sphere" size="0.0027646129541864144" pos="0.0 0.0 0.0" group="4" />
											<geom type="capsule" pos="0.0 0.0 0.010256714060031598" size="0.007187993680884677 0.007436808846761455" mass=".001563" condim="6" />
										</body>
									</body>
								</body>
								<body name="a_left_rfknuckle" pos="-0.016269747235387048 0.0 0.040708925750394954">
									<joint name="robot:a_left_rf_side" type="hinge" pos="0.0 0.0 0.0" axis="0 1 0" range="-25 25" stiffness=".003" damping="0.001" armature="0.0001" />
									<joint name="robot:a_left_rf_knuckle" type="hinge" pos="0.0 0.0 0.0" axis="-1 0 0" range="-20 90" springref="45" stiffness="0.0009" damping="0.0005" armature="0.0001" />
									<site name="a_torque_left_rf_knuckle" type="sphere" size="0.0027646129541864144" pos="0.0 0.0 0.0" group="4" />
									<geom type="capsule" pos="0.0 0.0 0.013518957345971567" size="0.007588862559241708 0.013518957345971567" mass=".002664" condim="6" />
									<body name="a_left_rfmiddle" pos="0.0 0.0 0.027037914691943134">
										<joint name="robot:a_left_rf_middle" type="hinge" pos="0.0 0.0 0.0" axis="-1 0 0" range="-5 100" springref="45" stiffness="0.0007" damping="0.0005" armature="0.0001" />
										<site name="a_torque_left_rf_middle" type="sphere" size="0.0027646129541864144" pos="0.0 0.0 0.0" group="4" />
										<geom type="capsule" pos="0.0 0.0 0.010961690363349132" size="0.007187993680884677 0.006759478672985784" mass=".001476" condim="6" />
										<body name="a_left_rfdistal" pos="0.0 0.0 0.017969984202211693">
											<joint name="robot:a_left_rf_distal" type="hinge" pos="0.0 0.0 0.0" axis="-1 0 0" range="-5 80" springref="30" stiffness="0.0006" damping="0.0005" armature="0.0001" />
											<site name="a_torque_left_rf_distal" type="sphere" size="0.0027646129541864144" pos="0.0 0.0 0.0" group="4" />
											<geom type="capsule" pos="0.0 0.0 0.009454976303317536" size="0.0069115323854660364 0.006621248025276462" mass=".001316" condim="6" />
										</body>
									</body>
								</body>
								<body name="a_left_lfmetacarpal" pos="-0.020706951026856244 0.0 0.004285150078988942">
									<joint name="robot:a_left_lf_meta" type="hinge" pos="0.0 0.0 0.0" axis="-0.571 0 0.821" range="0 40" stiffness=".01" damping=".001" armature="0.0001" />
									<site name="a_torque_left_lf_meta" type="sphere" size="0.0027646129541864144" pos="0.0 0.0 0.0" group="4" />
									<geom type="box" pos="-0.012205766192733019 0.0 0.007146524486571881" size="0.007022116903633493 0.00807266982622433 0.017859399684044236" mass=".002879" condim="6" contype="4" conaffinity="25" />
									<geom type="cylinder" pos="-0.012205766192733019 0.0 0.025005924170616117" size="0.00807266982622433 0.0069115323854660364" mass=".0009879" euler="0 90 0" condim="6" contype="4" conaffinity="25" />
									<body name="a_left_lfknuckle" pos="-0.011735781990521329 0.0 0.0314198262243286">
										<joint name="robot:a_left_lf_side" type="hinge" pos="0.0 0.0 0.0" axis="0 1 0" range="-25 25" stiffness="0.003" damping="0.001" armature="0.0001" />
										<joint name="robot:a_left_lf_knuckle" type="hinge" pos="0.0 0.0 0.0" axis="-1 0 0" range="-20 90" springref="45" stiffness="0.0007" damping="0.0005" armature="0.0001" />
										<site name="a_torque_left_lf_knuckle" type="sphere" size="0.0027646129541864144" pos="0.0 0.0 0.0" group="4" />
										<geom type="capsule" pos="0.0 0.0 0.011279620853080572" size="0.007312401263823066 0.011279620853080572" mass=".002143" condim="6" />
										<body name="a_left_lfmiddle" pos="0.0 0.0 0.02294628751974724">
											<joint name="robot:a_left_lf_middle" type="hinge" pos="0.0 0.0 0.0" axis="-1 0 0" range="-5 100" springref="45" stiffness="0.0006" damping="0.0005" armature="0.0001" />
											<site name="a_torque_left_lf_middle" type="sphere" size="0.0027646129541864144" pos="0.0 0.0 0.0" group="4" />
											<geom type="capsule" pos="0.0 0.0 0.0069115323854660364" size="0.0069115323854660364 0.006289494470774093" mass=".001276" condim="6" />
											<body name="a_left_lfdistal" pos="0.0 0.0 0.012717219589257506">
												<joint name="robot:a_left_lf_distal" type="hinge" pos="0.0 0.0 0.0" axis="-1 0 0" range="-5 80" springref="30" stiffness="0.0006" damping="0.0005" armature="0.0001" />
												<site name="a_torque_left_lf_distal" type="sphere" size="0.0027646129541864144" pos="0.0 0.0 0.0" group="4" />
												<geom type="capsule" pos="0.0 0.0 0.008238546603475515" size="0.006773301737756715 0.00540481832543444" mass=".001113" condim="6" />
											</body>
										</body>
									</body>
								</body>
								<body name="a_left_thbase" pos="0.017002369668246448 0.005847156398104267 -0.022144549763033178" euler="0 80 -30">
									<joint name="robot:a_left_th_swivel" type="hinge" pos="0.0 0.0 0.0" axis="-3 -5 1" range="-10 110" springref="40" stiffness="0.003" damping="0.001" armature="0.0001" />
									<joint name="robot:a_left_th_adduction" type="hinge" pos="0.0 0.0 0.0" axis="-1 2 0" range="-60 0" springref="-35" stiffness="0.004" damping="0.001" armature="0.0001" />
									<site name="a_torque_left_th_base" type="sphere" size="0.0027646129541864144" pos="0.0 0.0 0.0" group="4" />
									<geom type="capsule" pos="0.0 0.0 0.014196287519747237" size="0.010173775671406005 0.014196287519747237" mass=".005463" condim="6" contype="4" conaffinity="25" />
									<body name="a_left_thhub" pos="0.0 0.0 0.029374012638230654">
										<joint name="robot:a_left_th_pivot" type="hinge" pos="0.0 0.0 0.0" axis="-1 0 0" range="-10 10" springref="0" stiffness="0.002" damping="0.001" armature="0.0001" />
										<joint name="robot:a_left_th_middle" type="hinge" pos="0.0 0.0 0.0" axis="0 -1 0" range="0 90" springref="30" stiffness="0.004" damping="0.001" armature="0.0001" />
										<site name="a_torque_left_th_hub" type="sphere" size="0.0027646129541864144" pos="0.0 0.0 0.0" group="4" />
										<geom type="capsule" pos="0.0 0.0 0.011749605055292262" size="0.008819115323854662 0.009634676145339654" mass=".003021" condim="6" />
										<body name="a_left_thdistal" pos="0.0 0.0 0.020734597156398107">
											<joint name="robot:a_left_th_distal" type="hinge" pos="0.0 0.0 0.0" axis="0 -1 0" range="0 90" springref="20" stiffness="0.004" damping="0.001" armature="0.0001" />
											<site name="a_torque_left_th_distal" type="sphere" size="0.0027646129541864144" pos="0.0 0.0 0.0" group="4" />
											<geom type="capsule" pos="0.0 0.0 0.013767772511848344" size="0.00854265402843602 0.008114139020537127" mass=".002509" condim="6" />
										</body>
									</body>
								</body>
							</body>
						</body>
					</body>
				</body>
			</body>
		</body>
		<body name="a_right_upper_leg" pos="0 -0.095 -0.039999999999999994" euler="0 0 0">
			<joint name="robot:a_right_hip1" type="hinge" pos="0 0 0" axis="0 -1 0" springref="-10" range="-133 20" stiffness="1.72" damping="1.27" frictionloss=".08" armature=".005" />
			<joint name="robot:a_right_hip2" type="hinge" pos="0 0 0" axis="1 0 0" range="-51 17" stiffness="3.51" damping="1.99" frictionloss=".062" armature=".005" />
			<joint name="robot:a_right_hip3" type="hinge" pos="0 0 0" axis="0 0 1" range="-32 41" stiffness="2.16" damping="0.75" frictionloss=".027" armature=".005" />
			<site name="a_torque_right_hip" type="sphere" size="0.01" pos="0 0 0" group="4" />
			<geom name="a_right_uleg" type="capsule" material="pants_down" contype="2" conaffinity="3" size="0.085 0.215" mass="6.168749999999999" pos="0 0 -0.215" euler="0 0 0" />
			<body name="a_right_lower_leg" pos="0 0 -0.43">
				<joint name="robot:a_right_knee1" type="hinge" pos="0 0 0" axis="0 -1 0" springref="-30" range="-145 4" stiffness="1.63" damping="0.53" frictionloss=".065" armature=".003" />
				<joint name="robot:a_right_knee2" type="hinge" pos="0 0 0" axis="1 0 0" springref="-30" range="-145 4" stiffness="1.63" damping="0.53" frictionloss=".065" armature=".003" />
				<joint name="robot:a_right_knee3" type="hinge" pos="0 0 0" axis="0 0 1" springref="-30" range="-145 4" stiffness="1.63" damping="0.53" frictionloss=".065" armature=".003" />
				<site name="a_torque_right_knee" type="sphere" size="0.01" pos="0 0 0" group="4" />
				<geom name="a_right_lleg" type="capsule" material="pants_leg" size="0.05 0.205" mass="3.745" pos="0 0 -0.205" />
				<body name="a_right_foot" pos="0 0 -0.45999999999999996">
					<joint name="robot:a_right_foot1" type="hinge" pos="0.0 0.0 0.0" axis="0 -1 0" springref="-10" range="-63 32" stiffness="1.29" damping="0.6" frictionloss=".019" armature=".003" />
					<joint name="robot:a_right_foot2" type="hinge" pos="0.0 0.0 0.0" axis="1 0 0" range="-33 31" stiffness="0.96" damping="0.37" frictionloss=".011" armature=".0025" />
					<joint name="robot:a_right_foot3" type="hinge" pos="0.0 0.0 0.0" axis="0 0 1" range="-20 30" stiffness="1.15" damping="0.38" frictionloss=".012" armature=".002" />
					<site name="a_torque_right_ankle" type="sphere" size="0.03" pos="0.0 0.0 0.0" group="4" />
					<geom type="cylinder" size="0.047 0.0303" mass=".03225" pos="0.0 0.0 0.0" euler="0 0 0" />
					<geom type="box" size="0.0675 0.04795 0.03" mass=".04923" pos="0.0675 0.0 0.0" euler="0 0 0" friction="2 0.02 0.01" />
					<geom type="cylinder" size="0.0303 0.04795" mass=".01312" pos="0.135 0.0 0.0" euler="90 0 0" friction="2 0.02 0.01" />
					<body name="a_right_big_toe" pos="0.112 0.0369 0.0">
						<joint name="robot:a_right_big_toe" type="hinge" pos="0.0 0.0 0.0" axis="0 -1 0" range="-60 80" frictionloss=".002" armature=".0001" stiffness=".053" damping=".02" />
						<site name="a_torque_right_big_toe" type="sphere" size="0.03" pos="0.0 0.0 0.0" group="4" />
						<geom type="box" size="0.028499999999999998 0.011 0.029700000000000004" mass=".004425" pos="0.028499999999999998 0.0 0.0" euler="0 0 0" friction="2 0.02 0.01" />
						<geom type="cylinder" size="0.03 0.012" mass=".003934" pos="0.056999999999999995 0.0 0.0" euler="90 0 0" friction="2 0.02 0.01" />
					</body>
					<body name="a_right_toes" pos="0.112 -0.0141 0.0">
						<joint name="robot:a_right_toes" type="hinge" pos="0.0 0.0 0.0" axis="0 -1 0" range="-60 80" frictionloss=".002" armature=".0001" stiffness=".053" damping=".02" />
						<site name="a_torque_right_toes" type="sphere" size="0.03" pos="0.0 0.0 0.0" group="4" />
						<geom type="box" size="0.028499999999999998 0.034 0.029700000000000004" mass=".01006" pos="0.028499999999999998 0.0 0.0" euler="0 0 0" friction="2 0.02 0.01" />
						<geom type="cylinder" size="0.03 0.0345" mass=".008612" pos="0.056999999999999995 0.0 0.0" euler="90 0 0" friction="2 0.02 0.01" />
					</body>
				</body>
			</body>
		</body>
		<body name="a_left_upper_leg" pos="0 0.095 -0.039999999999999994" euler="0 0 0">
			<joint name="robot:a_left_hip1" type="hinge" pos="0 0 0" axis="0 -1 0" springref="-10" range="-133 20" stiffness="1.72" damping="1.27" frictionloss=".08" armature=".005" />
			<joint name="robot:a_left_hip2" type="hinge" pos="0 0 0" axis="1 0 0" range="-51 17" stiffness="3.51" damping="1.99" frictionloss=".062" armature=".005" />
			<joint name="robot:a_left_hip3" type="hinge" pos="0 0 0" axis="0 0 1" range="-32 41" stiffness="2.16" damping="0.75" frictionloss=".027" armature=".005" />
			<site name="a_torque_left_hip" type="sphere" size="0.01" pos="0 0 0" group="4" />
			<geom name="a_left_uleg" type="capsule" material="pants_down" contype="2" conaffinity="3" size="0.085 0.215" mass="6.168749999999999" pos="0 0 -0.215" euler="0 0 0" />
			<body name="a_left_lower_leg" pos="0 0 -0.43">
				<joint name="robot:a_left_knee1" type="hinge" pos="0 0 0" axis="0 -1 0" springref="-30" range="-145 4" stiffness="1.63" damping="0.53" frictionloss=".065" armature=".003" />
				<joint name="robot:a_left_knee2" type="hinge" pos="0 0 0" axis="1 0 0" springref="-30" range="-145 4" stiffness="1.63" damping="0.53" frictionloss=".065" armature=".003" />
				<joint name="robot:a_left_knee3" type="hinge" pos="0 0 0" axis="0 0 1" springref="-30" range="-145 4" stiffness="1.63" damping="0.53" frictionloss=".065" armature=".003" />
				<site name="a_torque_left_knee" type="sphere" size="0.01" pos="0 0 0" group="4" />
				<geom name="a_left_lleg" type="capsule" material="pants_leg" size="0.05 0.205" mass="3.745" pos="0 0 -0.205" euler="0 0 0" />
				<body name="a_left_foot" pos="0 0 -0.45999999999999996">
					<joint name="robot:a_left_foot1" type="hinge" pos="0.0 0.0 0.0" axis="0 -1 0" springref="-10" range="-63 32" stiffness="1.29" damping="0.6" frictionloss=".019" armature=".003" />
					<joint name="robot:a_left_foot2" type="hinge" pos="0.0 0.0 0.0" axis="1 0 0" range="-33 31" stiffness="0.96" damping="0.37" frictionloss=".011" armature=".0025" />
					<joint name="robot:a_left_foot3" type="hinge" pos="0.0 0.0 0.0" axis="0 0 1" range="-20 30" stiffness="1.15" damping="0.38" frictionloss=".012" armature=".002" />
					<site name="a_torque_left_ankle" type="sphere" size="0.03" pos="0.0 0.0 0.0" group="4" />
					<geom type="cylinder" size="0.047 0.0303" mass=".03225" pos="0.0 0.0 0.0" euler="0 0 0" />
					<geom type="box" size="0.0675 0.04795 0.03" mass=".04923" pos="0.0675 0.0 0.0" euler="0 0 0" friction="2 0.02 0.01" />
					<geom type="cylinder" size="0.0303 0.04795" mass=".01312" pos="0.135 0.0 0.0" euler="90 0 0" friction="2 0.02 0.01" />
					<body name="a_left_toes" pos="0.112 0.0141 0.0">
						<joint name="robot:a_left_toes" type="hinge" pos="0.0 0.0 0.0" axis="0 -1 0" range="-60 80" frictionloss=".002" armature=".0001" stiffness=".053" damping=".02" />
						<site name="a_torque_left_toes" type="sphere" size="0.03" pos="0.0 0.0 0.0" group="4" />
						<geom type="box" size="0.028499999999999998 0.034 0.029700000000000004" mass=".01006" pos="0.028499999999999998 0.0 0.0" euler="0 0 0" friction="2 0.02 0.01" />
						<geom type="cylinder" size="0.03 0.0345" mass=".008612" pos="0.056999999999999995 0.0 0.0" euler="90 0 0" friction="2 0.02 0.01" />
					</body>
					<body name="a_left_big_toe" pos="0.112 -0.0369 0.0">
						<joint name="robot:a_left_big_toe" type="hinge" pos="0.0 0.0 0.0" axis="0 -1 0" range="-60 80" frictionloss=".002" armature=".0001" stiffness=".053" damping=".02" />
						<site name="a_torque_left_big_toe" type="sphere" size="0.03" pos="0.0 0.0 0.0" group="4" />
						<geom type="box" size="0.028499999999999998 0.011 0.029700000000000004" mass=".004425" pos="0.028499999999999998 0.0 0.0" euler="0 0 0" friction="2 0.02 0.01" />
						<geom type="cylinder" size="0.03 0.012" mass=".003934" pos="0.056999999999999995 0.0 0.0" euler="90 0 0" friction="2 0.02 0.01" />
					</body>
				</body>
			</body>
		</body>
	</body>
</mujoco>