<mujoco model="MIMo">
    <body childclass="mimo" name="hip" pos="0 0 0">
        
        
        <!-- <body name="body" pos="0 0 0.000"> -->
            <geom name="lb" type="capsule" size="0.027 0.024" mass="1.1684" material="pants_down" pos="0 0 0.000" euler="90 0 0" />
            <site name="lowerBody_center" type="sphere" size=".01 .01 .01" pos="0 0 0.000" />

            <body name="lower_body" pos="0 0 0.043">
                <joint name="robot:hip_lean1" type="hinge" pos="0 0 -0.028" axis="1 0 0" range="-14 14" stiffness="3.38" damping="0.77" frictionloss=".049" armature="0.01" />
                <joint name="robot:hip_rot1" type="hinge" pos="0 0 -0.028" axis="0 0 1" range="-18 18" stiffness="1.45" damping="0.29" frictionloss=".018" armature="0.01" />
                <joint name="robot:hip_bend1" type="hinge" pos="0 0 -0.028" axis="0 1 0" range="-17 30.5" stiffness="2.20" damping="0.84" frictionloss="0.040" armature="0.01" />
                <site name="torque_lb" type="sphere" size="0.01" pos="0 0 0.000" group="4" />
                <geom name="cb" type="capsule" size="0.030 0.022" mass="1.3359" material="pants_up" contype="0" pos="0 0 -0.005" euler="90 0 0" />

                <body name="upper_body" pos="-.002 0 0.051">
                    <joint name="robot:hip_lean2" type="hinge" pos="0 0 -0.028" axis="1 0 0" range="-27 27" stiffness="1.69" damping="0.38" frictionloss=".024" armature="0.01" />
                    <joint name="robot:hip_rot2" type="hinge" pos="0 0 -0.028" axis="0 0 1" range="-18 18" stiffness="1.45" damping="0.29" frictionloss=".018" armature="0.01" />
                    <joint name="robot:hip_bend2" type="hinge" pos="0 0 -0.028" axis="0 1 0" range="-17 30.5" stiffness="2.20" damping="0.84" frictionloss="0.040" armature="0.01" />
                    <site name="torque_ub" type="sphere" size="0.01" pos="0 0 0.000" group="4" />
                    <geom name="ub1" type="capsule" size="0.029 0.022" mass="1.0976" material="top_down" pos="0.007 0 -0.018" euler="90 0 0" />
                    <geom name="ub2" type="capsule" size="0.027 0.024" mass="0.9531" material="top_middle" pos="0.004 0 0.017" euler="90 0 0" />
                    <geom name="ub3" type="capsule" size="0.023 0.028" mass="0.7279" material="top_up" pos="0 0 0.051" euler="90 0 0" />

                    <body name="head" pos="0 0 0.07599337748344373">
                        <geom name="head" type="sphere" material="head" size=".0602" mass="1.7901" pos="0.01 0 0.0602" />
                        <site name="vestibular" type="sphere" size="0.01" pos="0.01 0 0.0735" group="4" />
                        <site name="torque_neck" type="sphere" size="0.01" pos="0 0 0" group="4" />
                        <joint name="robot:head_swivel" type="hinge" pos="0 0 0" axis="0 0 1" range="-111 111" stiffness=".23" damping=".29" frictionloss=".018" armature="0.005" />
                        <joint name="robot:head_tilt" type="hinge" pos="0 0 0.0123" axis="0 1 0" range="-70 81" stiffness=".45" damping=".53" frictionloss=".018" armature="0.005" />
                        <joint name="robot:head_tilt_side" type="hinge" pos="0 0 0.0245" axis="1 0 0" range="-70 70" stiffness=".37" damping=".29" frictionloss=".018" armature="0.005" />
                        <body name="left_eye" pos=".06 .0235 .058">
                            <site name="torque_left_eye" type="sphere" size="0.01" pos="0 0 0" group="4" />
                            <joint name="robot:left_eye_horizontal" type="hinge" pos="0 0 0" axis="0 0 1" range="-45 45" stiffness=".00065" damping=".00042" frictionloss=".000054" armature=".0002" />
                            <joint name="robot:left_eye_vertical" type="hinge" pos="0 0 0" axis="0 -1 0" range="-47 33" stiffness=".00065" damping=".00042" frictionloss=".000054" armature=".0002" />
                            <joint name="robot:left_eye_torsional" type="hinge" pos="0 0 0" axis="-1 0 0" range="-8 8" stiffness=".00267" damping=".00042" frictionloss=".000037" armature=".0002" />
                            <geom type="sphere" material="eye_left" size=".01125" mass="0.006329" pos="0 0 0" />
                            <camera name="eye_left" mode="fixed" fovy="60" pos="0.01125 0 0" euler="90 -90 0" />
                        </body>
                        <body name="right_eye" pos=".06 -.0235 .058">
                            <site name="torque_right_eye" type="sphere" size="0.01" pos="0 0 0" group="4" />
                            <joint name="robot:right_eye_horizontal" type="hinge" pos="0 0 0" axis="0 0 -1" range="-45 45" stiffness=".00065" damping=".00042" frictionloss=".000054" armature=".0002" />
                            <joint name="robot:right_eye_vertical" type="hinge" pos="0 0 0" axis="0 -1 0" range="-47 33" stiffness=".00065" damping=".00042" frictionloss=".000054" armature=".0002" />
                            <joint name="robot:right_eye_torsional" type="hinge" pos="0 0 0" axis="1 0 0" range="-8 8" stiffness=".00267" damping=".00042" frictionloss=".000037" armature=".0002" />
                            <geom type="sphere" material="eye_right" size=".01125" mass="0.006329" pos="0 0 0" />
                            <camera name="eye_right" mode="fixed" fovy="60" pos="0.01125 0 0" euler="90 -90 0" />
                        </body>
                    </body>

                    <body name="right_upper_arm" pos="0 -0.0575 0.06" euler="170 0 0">
					
					<joint name="robot:right_shoulder_horizontal" type="hinge" pos="0 0 0" axis="0 1 -4" range="-28 118" stiffness=".09" damping=".05" frictionloss=".0009" armature="0.004" />
					<joint name="robot:right_shoulder_ad_ab" type="hinge" pos="0 0 0" axis="-1 0 0" range="-84 183" stiffness=".11" damping=".10" frictionloss=".0014" armature="0.004" />
					<joint name="robot:right_shoulder_rotation" type="hinge" pos="0 0 0" axis="0 0 -1" range="-99 67" stiffness=".12" damping=".07" frictionloss=".0008" armature="0.004" />
					<site name="torque_right_shoulder" type="sphere" size="0.01" pos="0 0 0" group="4" />
					<geom name="right_uarm1" type="capsule" material="top_sleeve" size="0.016399999999999998 0.0425" mass="0.2708" pos="0 0 0.0425" euler="0 0 0" />
					<body name="right_lower_arm" pos="0 0 0.085" euler="0 0 0">
						<joint name="robot:right_elbow" type="hinge" pos="0 0 0" axis="0 -1 0" springref="-20" range="-146 5" stiffness=".13" damping=".11" frictionloss=".030" armature="0.002" />
						<site name="torque_right_elbow" type="sphere" size="0.01" pos="0 0 0" group="4" />
						<geom name="right_larm" type="capsule" size="0.0145 0.0265" mass="0.1869" pos="0 0 0.0265" contype="8" conaffinity="7" />
						<body name="right_hand" pos="0 0 0.081" euler="0 0 0"> 
							<joint name="robot:right_hand1" type="hinge" pos="0.0 0.0 0.0" axis="0 0 -1" springref="-20" range="-90 90" stiffness=".22" damping=".03" frictionloss=".007" armature="0.001" />
							<joint name="robot:right_hand2" type="hinge" pos="0.0 0.0 0.0" axis="-1 0 0" range="-92 86" stiffness=".33" damping=".11" frictionloss=".007" armature="0.001" />
							<joint name="robot:right_hand3" type="hinge" pos="0.0 0.0 0.0" axis="0 1 0" range="-53 48" stiffness=".38" damping=".11" frictionloss=".007" armature="0.001" />
							<site name="torque_right_wrist" type="sphere" size="0.0010663507109004739" pos="0.0 0.0 0.0" group="4" />
							<geom type="box" pos="0.0 0.0 0.0" size="0.009127962085308057 0.003113744075829384 0.0135" mass="0.01895" condim="6" />
							<geom type="box" pos="-0.01226303317535545 0.0 -0.0066113744075829385" size="0.0031350710900473933 0.003113744075829384 0.006888625592417061" mass=".003321" condim="6" />
							<geom type="cylinder" pos="0.0 0.0 0.0135" size="0.003113744075829384 0.009117298578199052" mass=".003367" euler="0 90 0" condim="6" />
							<geom type="cylinder" pos="-0.0031350710900473933 0.0 -0.0135" size="0.003113744075829384 0.012252369668246445" mass=".004524" euler="0 90 0" condim="6" />
							
							<body name="right_ffknuckle" pos="0.006275473933649289 0.0 0.01570201421800948">
								<joint name="robot:right_ff_side" type="hinge" pos="0.0 0.0 0.0" axis="0 1 0" range="-25 25" stiffness=".003" damping="0.001" armature="0.0001" />
								<joint name="robot:right_ff_knuckle" type="hinge" pos="0.0 0.0 0.0" axis="1 0 0" range="-20 90" springref="45" stiffness="0.0008" damping="0.0005" armature="0.0001" />
								<site name="torque_right_ff_knuckle" type="sphere" size="0.0010663507109004739" pos="0.0 0.0 0.0" group="4" />
								<geom type="capsule" pos="0.0 0.0 0.0052890995260663504" size="0.002927132701421801 0.0052890995260663504" mass=".002692" condim="6" />
								
								<body name="right_ffmiddle" pos="0.0 0.0 0.010583530805687203">
									<joint name="robot:right_ff_middle" type="hinge" pos="0.0 0.0 0.0" axis="1 0 0" range="-5 100" springref="45" stiffness="0.0006" damping="0.0005" armature="0.0001" />
									<site name="torque_right_ff_middle" type="sphere" size="0.0010663507109004739" pos="0.0 0.0 0.0" group="4" />
									<geom type="capsule" pos="0.0 0.0 0.00429739336492891" size="0.002772511848341232 0.002671208530805687" mass=".001497" condim="6" />
									
									<body name="right_ffdistal" pos="0.0 0.0 0.007197867298578199">
										<joint name="robot:right_ff_distal" type="hinge" pos="0.0 0.0 0.0" axis="1 0 0" range="-5 80" springref="30" stiffness="0.0006" damping="0.0005" armature="0.0001" />
										<site name="torque_right_ff_distal" type="sphere" size="0.0010663507109004739" pos="0.0 0.0 0.0" group="4" />
										<geom type="capsule" pos="0.0 0.0 0.0035669431279620853" size="0.002665876777251185 0.0024739336492890997" mass=".001291" condim="6" />
									</body>
								</body>
							</body>
							
							<body name="right_mfknuckle" pos="0.0 0.0 0.01680568720379147">
								<joint name="robot:right_mf_side" type="hinge" pos="0.0 0.0 0.0" axis="0 1 0" range="-25 25" stiffness=".003" damping="0.001" armature="0.0001" />
								<joint name="robot:right_mf_knuckle" type="hinge" pos="0.0 0.0 0.0" axis="1 0 0" range="-20 90" springref="45" stiffness="0.0010" damping="0.0005" armature="0.0001" />
								<site name="torque_right_mf_knuckle" type="sphere" size="0.0010663507109004739" pos="0.0 0.0 0.0" group="4" />
								<geom type="capsule" pos="0.0 0.0 0.0058649289099526065" size="0.003087085308056872 0.0058649289099526065" mass=".003284" condim="6" />
								
								<body name="right_mfmiddle" pos="0.0 0.0 0.011729857819905213">
									<joint name="robot:right_mf_middle" type="hinge" pos="0.0 0.0 0.0" axis="1 0 0" range="-5 100" springref="45" stiffness="0.0007" damping="0.0005" armature="0.0001" />
									<site name="torque_right_mf_middle" type="sphere" size="0.0010663507109004739" pos="0.0 0.0 0.0" group="4" />
									<geom type="capsule" pos="0.0 0.0 0.004622630331753555" size="0.0028791469194312798 0.002996445497630332" mass=".001757" condim="6" />
									
									<body name="right_mfdistal" pos="0.0 0.0 0.007731042654028437">
										<joint name="robot:right_mf_distal" type="hinge" pos="0.0 0.0 0.0" axis="1 0 0" range="-5 80" springref="30" stiffness="0.0006" damping="0.0005" armature="0.0001" />
										<site name="torque_right_mf_distal" type="sphere" size="0.0010663507109004739" pos="0.0 0.0 0.0" group="4" />
										<geom type="capsule" pos="0.0 0.0 0.003956161137440759" size="0.002772511848341232 0.002868483412322275" mass=".001563" condim="6" />
									</body>
								</body>
							</body>
							
							<body name="right_rfknuckle" pos="-0.006275473933649289 0.0 0.01570201421800948">
								<joint name="robot:right_rf_side" type="hinge" pos="0.0 0.0 0.0" axis="0 1 0" range="-25 25" stiffness=".003" damping="0.001" armature="0.0001" />
								<joint name="robot:right_rf_knuckle" type="hinge" pos="0.0 0.0 0.0" axis="1 0 0" range="-20 90" springref="45" stiffness="0.0009" damping="0.0005" armature="0.0001" />
								<site name="torque_right_rf_knuckle" type="sphere" size="0.0010663507109004739" pos="0.0 0.0 0.0" group="4" />
								<geom type="capsule" pos="0.0 0.0 0.005214454976303318" size="0.002927132701421801 0.005214454976303318" mass=".002664" condim="6" />
								
								<body name="right_rfmiddle" pos="0.0 0.0 0.010428909952606636">
									<joint name="robot:right_rf_middle" type="hinge" pos="0.0 0.0 0.0" axis="1 0 0" range="-5 100" springref="45" stiffness="0.0007" damping="0.0005" armature="0.0001" />
									<site name="torque_right_rf_middle" type="sphere" size="0.0010663507109004739" pos="0.0 0.0 0.0" group="4" />
									<geom type="capsule" pos="0.0 0.0 0.004228080568720379" size="0.002772511848341232 0.002607227488151659" mass=".001476" condim="6" />
									
									<body name="right_rfdistal" pos="0.0 0.0 0.00693127962085308">
										<joint name="robot:right_rf_distal" type="hinge" pos="0.0 0.0 0.0" axis="1 0 0" range="-5 80" springref="30" stiffness="0.0006" damping="0.0005" armature="0.0001" />
										<site name="torque_right_rf_distal" type="sphere" size="0.0010663507109004739" pos="0.0 0.0 0.0" group="4" />
										<geom type="capsule" pos="0.0 0.0 0.0036469194312796207" size="0.002665876777251185 0.002553909952606635" mass=".001316" condim="6" />
									</body>
								</body>
							</body>
							
							<body name="right_lfmetacarpal" pos="-0.00798696682464455 0.0 0.0016528436018957346">
								<joint name="robot:right_lf_meta" type="hinge" pos="0.0 0.0 0.0" axis="0.571 0 0.821" range="0 40" stiffness=".01" damping=".001" armature="0.0001" />
								<site name="torque_right_lf_meta" type="sphere" size="0.0010663507109004739" pos="0.0 0.0 0.0" group="4" />
								<geom type="box" pos="-0.004707938388625592 0.0 0.002756516587677725" size="0.002708530805687204 0.003113744075829384 0.006888625592417061" mass=".002879" condim="6" contype="16" conaffinity="7" />
								<geom type="cylinder" pos="-0.004707938388625592 0.0 0.009645142180094785" size="0.003113744075829384 0.002665876777251185" mass=".0009879" euler="0 90 0" condim="6" contype="16" conaffinity="7" />
								
								<body name="right_lfknuckle" pos="-0.004526658767772512 0.0 0.012119075829383886">
									<joint name="robot:right_lf_side" type="hinge" pos="0.0 0.0 0.0" axis="0 1 0" range="-25 25" stiffness="0.003" damping="0.001" armature="0.0001" />
									<joint name="robot:right_lf_knuckle" type="hinge" pos="0.0 0.0 0.0" axis="1 0 0" range="-20 90" springref="45" stiffness="0.0007" damping="0.0005" armature="0.0001" />
									<site name="torque_right_lf_knuckle" type="sphere" size="0.0010663507109004739" pos="0.0 0.0 0.0" group="4" />
									<geom type="capsule" pos="0.0 0.0 0.004350710900473934" size="0.0028204976303317537 0.004350710900473934" mass=".002143" condim="6" />
									
									<body name="right_lfmiddle" pos="0.0 0.0 0.008850710900473934">
										<joint name="robot:right_lf_middle" type="hinge" pos="0.0 0.0 0.0" axis="1 0 0" range="-5 100" springref="45" stiffness="0.0006" damping="0.0005" armature="0.0001" />
										<site name="torque_right_lf_middle" type="sphere" size="0.0010663507109004739" pos="0.0 0.0 0.0" group="4" />
										<geom type="capsule" pos="0.0 0.0 0.002665876777251185" size="0.002665876777251185 0.0024259478672985784" mass=".001276" condim="6" />
										
										<body name="right_lfdistal" pos="0.0 0.0 0.00490521327014218">
											<joint name="robot:right_lf_distal" type="hinge" pos="0.0 0.0 0.0" axis="1 0 0" range="-5 80" springref="30" stiffness="0.0006" damping="0.0005" armature="0.0001" />
											<site name="torque_right_lf_distal" type="sphere" size="0.0010663507109004739" pos="0.0 0.0 0.0" group="4" />
											<geom type="capsule" pos="0.0 0.0 0.0031777251184834125" size="0.002612559241706161 0.002084715639810427" mass=".001113" condim="6" />
										</body>
									</body>
								</body>
							</body>
							
							<body name="right_thbase" pos="0.006558056872037915 -0.0022553317535545024 -0.008541469194312796" euler="0 80 30">
								<joint name="robot:right_th_swivel" type="hinge" pos="0.0 0.0 0.0" axis="3 -5 -1" range="-10 110" springref="40" stiffness="0.003" damping="0.001" armature="0.0001" />
								<joint name="robot:right_th_adduction" type="hinge" pos="0.0 0.0 0.0" axis="1 2 0" range="-60 0" springref="-35" stiffness="0.004" damping="0.001" armature="0.0001" />
								
								<site name="torque_right_th_base" type="sphere" size="0.0010663507109004739" pos="0.0 0.0 0.0" group="4" />
								<geom type="capsule" pos="0.0 0.0 0.005475710900473933" size="0.0039241706161137445 0.005475710900473933" mass=".005463" condim="6" contype="16" conaffinity="7" />
								
								<body name="right_thhub" pos="0.0 0.0 0.011329976303317536">
									<joint name="robot:right_th_pivot" type="hinge" pos="0.0 0.0 0.0" axis="1 0 0" range="-10 10" springref="0" stiffness="0.002" damping="0.001" armature="0.0001" />
									<joint name="robot:right_th_middle" type="hinge" pos="0.0 0.0 0.0" axis="0 -1 0" range="0 90" springref="30" stiffness="0.004" damping="0.001" armature="0.0001" />
									<site name="torque_right_th_hub" type="sphere" size="0.0010663507109004739" pos="0.0 0.0 0.0" group="4" />
									<geom type="capsule" pos="0.0 0.0 0.004531990521327015" size="0.003401658767772512 0.0037162322274881514" mass=".003021" condim="6" />
									
									<body name="right_thdistal" pos="0.0 0.0 0.007997630331753554">
										<joint name="robot:right_th_distal" type="hinge" pos="0.0 0.0 0.0" axis="0 -1 0" range="0 90" springref="20" stiffness="0.004" damping="0.001" armature="0.0001" />
										<site name="torque_right_th_distal" type="sphere" size="0.0010663507109004739" pos="0.0 0.0 0.0" group="4" />
										<geom type="capsule" pos="0.0 0.0 0.005310426540284361" size="0.0032950236966824645 0.003129739336492891" mass=".002509" condim="6" />
									</body>
								</body>
							</body>
						</body> 
					</body>
				</body>

                    <body name="left_upper_arm" pos="0 0.0575 0.06" euler="-170 0 0">
					
					<joint name="robot:left_shoulder_horizontal" type="hinge" pos="0 0 0" axis="0 1 4" range="-28 118" stiffness=".09" damping=".05" frictionloss=".0009" armature="0.004" />
					<joint name="robot:left_shoulder_ad_ab" type="hinge" pos="0 0 0" axis="1 0 0" range="-84 183" stiffness=".11" damping=".10" frictionloss=".0014" armature="0.004" />
					<joint name="robot:left_shoulder_rotation" type="hinge" pos="0 0 0" axis="0 0 1" range="-99 67" stiffness=".12" damping=".07" frictionloss=".0008" armature="0.004" />
					<site name="torque_left_shoulder" type="sphere" size="0.01" pos="0 0 0" group="4" />
					<geom name="left_uarm1" type="capsule" material="top_sleeve" size="0.016399999999999998 0.0425" mass="0.2708" pos="0 0 0.0425" euler="0 0 0" />
					<body name="left_lower_arm" pos="0 0 0.085" euler="0 0 0">
						<joint name="robot:left_elbow" type="hinge" pos="0 0 0" axis="0 -1 0" springref="-20" range="-146 5" stiffness=".13" damping=".11" frictionloss=".030" armature="0.002" />
						<site name="torque_left_elbow" type="sphere" size="0.01" pos="0 0 0" group="4" />
						<geom name="left_larm" type="capsule" size="0.0145 0.0265" mass="0.1869" pos="0 0 0.0265" contype="2" conaffinity="25" />
						<body name="left_hand" pos="0 0 0.081" euler="0 0 0"> 
							<joint name="robot:left_hand1" type="hinge" pos="0.0 0.0 0.0" axis="0 0 1" springref="-20" range="-90 90" stiffness=".22" damping=".03" frictionloss=".007" armature="0.001" />
							<joint name="robot:left_hand2" type="hinge" pos="0.0 0.0 0.0" axis="1 0 0" range="-92 86" stiffness=".33" damping=".11" frictionloss=".007" armature="0.001" />
							<joint name="robot:left_hand3" type="hinge" pos="0.0 0.0 0.0" axis="0 1 0" range="-53 48" stiffness=".38" damping=".11" frictionloss=".007" armature="0.001" />
							<site name="torque_left_wrist" type="sphere" size="0.0010663507109004739" pos="0.0 0.0 0.0" group="4" />
							<geom type="box" pos="0.0 0.0 0.0" size="0.009127962085308057 0.003113744075829384 0.0135" mass="0.01895" condim="6" />
							<geom type="box" pos="-0.01226303317535545 0.0 -0.0066113744075829385" size="0.0031350710900473933 0.003113744075829384 0.006888625592417061" mass=".003321" condim="6" />
							<geom type="cylinder" pos="0.0 0.0 0.0135" size="0.003113744075829384 0.009117298578199052" mass=".003367" euler="0 90 0" condim="6" />
							<geom type="cylinder" pos="-0.0031350710900473933 0.0 -0.0135" size="0.003113744075829384 0.012252369668246445" mass=".004524" euler="0 90 0" condim="6" />
							
							<body name="left_ffknuckle" pos="0.006275473933649289 0.0 0.01570201421800948">
								<joint name="robot:left_ff_side" type="hinge" pos="0.0 0.0 0.0" axis="0 1 0" range="-25 25" stiffness=".003" damping="0.001" armature="0.0001" />
								<joint name="robot:left_ff_knuckle" type="hinge" pos="0.0 0.0 0.0" axis="-1 0 0" range="-20 90" springref="45" stiffness="0.0008" damping="0.0005" armature="0.0001" />
								<site name="torque_left_ff_knuckle" type="sphere" size="0.0010663507109004739" pos="0.0 0.0 0.0" group="4" />
								<geom type="capsule" pos="0.0 0.0 0.0052890995260663504" size="0.002927132701421801 0.0052890995260663504" mass=".002692" condim="6" />
								
								<body name="left_ffmiddle" pos="0.0 0.0 0.010583530805687203">
									<joint name="robot:left_ff_middle" type="hinge" pos="0.0 0.0 0.0" axis="-1 0 0" range="-5 100" springref="45" stiffness="0.0006" damping="0.0005" armature="0.0001" />
									<site name="torque_left_ff_middle" type="sphere" size="0.0010663507109004739" pos="0.0 0.0 0.0" group="4" />
									<geom type="capsule" pos="0.0 0.0 0.00429739336492891" size="0.002772511848341232 0.002671208530805687" mass=".001497" condim="6" />
									
									<body name="left_ffdistal" pos="0.0 0.0 0.007197867298578199">
										<joint name="robot:left_ff_distal" type="hinge" pos="0.0 0.0 0.0" axis="-1 0 0" range="-5 80" springref="30" stiffness="0.0006" damping="0.0005" armature="0.0001" />
										<site name="torque_left_ff_distal" type="sphere" size="0.0010663507109004739" pos="0.0 0.0 0.0" group="4" />
										<geom type="capsule" pos="0.0 0.0 0.0035669431279620853" size="0.002665876777251185 0.0024739336492890997" mass=".001291" condim="6" />
									</body>
								</body>
							</body>
							
							<body name="left_mfknuckle" pos="0.0 0.0 0.01680568720379147">
								<joint name="robot:left_mf_side" type="hinge" pos="0.0 0.0 0.0" axis="0 1 0" range="-25 25" stiffness=".003" damping="0.001" armature="0.0001" />
								<joint name="robot:left_mf_knuckle" type="hinge" pos="0.0 0.0 0.0" axis="-1 0 0" range="-20 90" springref="45" stiffness="0.0010" damping="0.0005" armature="0.0001" />
								<site name="torque_left_mf_knuckle" type="sphere" size="0.0010663507109004739" pos="0.0 0.0 0.0" group="4" />
								<geom type="capsule" pos="0.0 0.0 0.0058649289099526065" size="0.003087085308056872 0.0058649289099526065" mass=".003284" condim="6" />
								
								<body name="left_mfmiddle" pos="0.0 0.0 0.011729857819905213">
									<joint name="robot:left_mf_middle" type="hinge" pos="0.0 0.0 0.0" axis="-1 0 0" range="-5 100" springref="45" stiffness="0.0007" damping="0.0005" armature="0.0001" />
									<site name="torque_left_mf_middle" type="sphere" size="0.0010663507109004739" pos="0.0 0.0 0.0" group="4" />
									<geom type="capsule" pos="0.0 0.0 0.004622630331753555" size="0.0028791469194312798 0.002996445497630332" mass=".001757" condim="6" />
									
									<body name="left_mfdistal" pos="0.0 0.0 0.007731042654028437">
										<joint name="robot:left_mf_distal" type="hinge" pos="0.0 0.0 0.0" axis="-1 0 0" range="-5 80" springref="30" stiffness="0.0006" damping="0.0005" armature="0.0001" />
										<site name="torque_left_mf_distal" type="sphere" size="0.0010663507109004739" pos="0.0 0.0 0.0" group="4" />
										<geom type="capsule" pos="0.0 0.0 0.003956161137440759" size="0.002772511848341232 0.002868483412322275" mass=".001563" condim="6" />
									</body>
								</body>
							</body>
							
							<body name="left_rfknuckle" pos="-0.006275473933649289 0.0 0.01570201421800948">
								<joint name="robot:left_rf_side" type="hinge" pos="0.0 0.0 0.0" axis="0 1 0" range="-25 25" stiffness=".003" damping="0.001" armature="0.0001" />
								<joint name="robot:left_rf_knuckle" type="hinge" pos="0.0 0.0 0.0" axis="-1 0 0" range="-20 90" springref="45" stiffness="0.0009" damping="0.0005" armature="0.0001" />
								<site name="torque_left_rf_knuckle" type="sphere" size="0.0010663507109004739" pos="0.0 0.0 0.0" group="4" />
								<geom type="capsule" pos="0.0 0.0 0.005214454976303318" size="0.002927132701421801 0.005214454976303318" mass=".002664" condim="6" />
								
								<body name="left_rfmiddle" pos="0.0 0.0 0.010428909952606636">
									<joint name="robot:left_rf_middle" type="hinge" pos="0.0 0.0 0.0" axis="-1 0 0" range="-5 100" springref="45" stiffness="0.0007" damping="0.0005" armature="0.0001" />
									<site name="torque_left_rf_middle" type="sphere" size="0.0010663507109004739" pos="0.0 0.0 0.0" group="4" />
									<geom type="capsule" pos="0.0 0.0 0.004228080568720379" size="0.002772511848341232 0.002607227488151659" mass=".001476" condim="6" />
									
									<body name="left_rfdistal" pos="0.0 0.0 0.00693127962085308">
										<joint name="robot:left_rf_distal" type="hinge" pos="0.0 0.0 0.0" axis="-1 0 0" range="-5 80" springref="30" stiffness="0.0006" damping="0.0005" armature="0.0001" />
										<site name="torque_left_rf_distal" type="sphere" size="0.0010663507109004739" pos="0.0 0.0 0.0" group="4" />
										<geom type="capsule" pos="0.0 0.0 0.0036469194312796207" size="0.002665876777251185 0.002553909952606635" mass=".001316" condim="6" />
									</body>
								</body>
							</body>
							
							<body name="left_lfmetacarpal" pos="-0.00798696682464455 0.0 0.0016528436018957346">
								<joint name="robot:left_lf_meta" type="hinge" pos="0.0 0.0 0.0" axis="-0.571 0 0.821" range="0 40" stiffness=".01" damping=".001" armature="0.0001" />
								<site name="torque_left_lf_meta" type="sphere" size="0.0010663507109004739" pos="0.0 0.0 0.0" group="4" />
								<geom type="box" pos="-0.004707938388625592 0.0 0.002756516587677725" size="0.002708530805687204 0.003113744075829384 0.006888625592417061" mass=".002879" condim="6" contype="4" conaffinity="25" />
								<geom type="cylinder" pos="-0.004707938388625592 0.0 0.009645142180094785" size="0.003113744075829384 0.002665876777251185" mass=".0009879" euler="0 90 0" condim="6" contype="4" conaffinity="25" />
								
								<body name="left_lfknuckle" pos="-0.004526658767772512 0.0 0.012119075829383886">
									<joint name="robot:left_lf_side" type="hinge" pos="0.0 0.0 0.0" axis="0 1 0" range="-25 25" stiffness="0.003" damping="0.001" armature="0.0001" />
									<joint name="robot:left_lf_knuckle" type="hinge" pos="0.0 0.0 0.0" axis="-1 0 0" range="-20 90" springref="45" stiffness="0.0007" damping="0.0005" armature="0.0001" />
									<site name="torque_left_lf_knuckle" type="sphere" size="0.0010663507109004739" pos="0.0 0.0 0.0" group="4" />
									<geom type="capsule" pos="0.0 0.0 0.004350710900473934" size="0.0028204976303317537 0.004350710900473934" mass=".002143" condim="6" />
									
									<body name="left_lfmiddle" pos="0.0 0.0 0.008850710900473934">
										<joint name="robot:left_lf_middle" type="hinge" pos="0.0 0.0 0.0" axis="-1 0 0" range="-5 100" springref="45" stiffness="0.0006" damping="0.0005" armature="0.0001" />
										<site name="torque_left_lf_middle" type="sphere" size="0.0010663507109004739" pos="0.0 0.0 0.0" group="4" />
										<geom type="capsule" pos="0.0 0.0 0.002665876777251185" size="0.002665876777251185 0.0024259478672985784" mass=".001276" condim="6" />
										
										<body name="left_lfdistal" pos="0.0 0.0 0.00490521327014218">
											<joint name="robot:left_lf_distal" type="hinge" pos="0.0 0.0 0.0" axis="-1 0 0" range="-5 80" springref="30" stiffness="0.0006" damping="0.0005" armature="0.0001" />
											<site name="torque_left_lf_distal" type="sphere" size="0.0010663507109004739" pos="0.0 0.0 0.0" group="4" />
											<geom type="capsule" pos="0.0 0.0 0.0031777251184834125" size="0.002612559241706161 0.002084715639810427" mass=".001113" condim="6" />
										</body>
									</body>
								</body>
							</body>
							
							<body name="left_thbase" pos="0.006558056872037915 0.0022553317535545024 -0.008541469194312796" euler="0 80 -30">
								<joint name="robot:left_th_swivel" type="hinge" pos="0.0 0.0 0.0" axis="-3 -5 1" range="-10 110" springref="40" stiffness="0.003" damping="0.001" armature="0.0001" />
								<joint name="robot:left_th_adduction" type="hinge" pos="0.0 0.0 0.0" axis="-1 2 0" range="-60 0" springref="-35" stiffness="0.004" damping="0.001" armature="0.0001" />
								
								<site name="torque_left_th_base" type="sphere" size="0.0010663507109004739" pos="0.0 0.0 0.0" group="4" />
								<geom type="capsule" pos="0.0 0.0 0.005475710900473933" size="0.0039241706161137445 0.005475710900473933" mass=".005463" condim="6" contype="4" conaffinity="25" />
								
								<body name="left_thhub" pos="0.0 0.0 0.011329976303317536">
									<joint name="robot:left_th_pivot" type="hinge" pos="0.0 0.0 0.0" axis="-1 0 0" range="-10 10" springref="0" stiffness="0.002" damping="0.001" armature="0.0001" />
									<joint name="robot:left_th_middle" type="hinge" pos="0.0 0.0 0.0" axis="0 -1 0" range="0 90" springref="30" stiffness="0.004" damping="0.001" armature="0.0001" />
									<site name="torque_left_th_hub" type="sphere" size="0.0010663507109004739" pos="0.0 0.0 0.0" group="4" />
									<geom type="capsule" pos="0.0 0.0 0.004531990521327015" size="0.003401658767772512 0.0037162322274881514" mass=".003021" condim="6" />
									
									<body name="left_thdistal" pos="0.0 0.0 0.007997630331753554">
										<joint name="robot:left_th_distal" type="hinge" pos="0.0 0.0 0.0" axis="0 -1 0" range="0 90" springref="20" stiffness="0.004" damping="0.001" armature="0.0001" />
										<site name="torque_left_th_distal" type="sphere" size="0.0010663507109004739" pos="0.0 0.0 0.0" group="4" />
										<geom type="capsule" pos="0.0 0.0 0.005310426540284361" size="0.0032950236966824645 0.003129739336492891" mass=".002509" condim="6" />
									</body>
								</body>
							</body>
						</body> 
					</body>
				</body>

                </body>
            </body>
        <!-- </body> -->

        <body name="right_upper_leg" pos="0 -0.03 0" euler="0 0 0">
            
            <joint name="robot:right_hip1" type="hinge" pos="0 0 0" axis="0 1 0" springref="-10" range="-133 20" stiffness="1.72" damping="1.27" frictionloss=".08" armature=".005" />
            <joint name="robot:right_hip2" type="hinge" pos="0 0 0" axis="1 0 0" range="-51 17" stiffness="3.51" damping="1.99" frictionloss=".062" armature=".005" />
            <joint name="robot:right_hip3" type="hinge" pos="0 0 0" axis="0 0 -1" range="-32 41" stiffness="2.16" damping="0.75" frictionloss=".027" armature=".005" />
            <site name="torque_right_hip" type="sphere" size="0.01" pos="0 0 0" group="4" />
            <geom name="right_uleg" type="capsule" material="pants_leg" contype="2" conaffinity="3" size="0.021500000000000002 0.045" mass=".8067" pos="0 0 -0.045" euler="0 0 0" />
            <body name="right_lower_leg" pos="0 0 -0.09">
                <joint name="robot:right_knee" type="hinge" pos="0 0 0" axis="0 -1 0" springref="-30" range="-145 4" stiffness="1.63" damping="0.53" frictionloss=".065" armature=".003" />
                <site name="torque_right_knee" type="sphere" size="0.01" pos="0 0 0" group="4" />
                <geom name="right_lleg" type="capsule" size="0.0183 0.032" mass=".3370" pos="0 0 -0.032" />
                <body name="right_foot" pos="0 0 -0.0873">
                    <joint name="robot:right_foot1" type="hinge" pos="0.0 0.0 0.0" axis="0 -1 0" springref="-10" range="-63 32" stiffness="1.29" damping="0.6" frictionloss=".019" armature=".003" />
                        <joint name="robot:right_foot2" type="hinge" pos="0.0 0.0 0.0" axis="1 0 0" range="-33 31" stiffness="0.96" damping="0.37" frictionloss=".011" armature=".0025" />
                        <joint name="robot:right_foot3" type="hinge" pos="0.0 0.0 0.0" axis="0 0 1" range="-20 30" stiffness="1.15" damping="0.38" frictionloss=".012" armature=".002" />
                        <site name="torque_right_ankle" type="sphere" size="0.01" pos="0.0 0.0 0.0" group="4" />
                        <geom type="cylinder" size="0.0249 0.0101" mass=".03225" pos="-0.007 0.0 0.0" euler="0 0 0" />
                        <geom type="box" size="0.03 0.025 0.01" mass=".04923" pos="0.023 0.0 0.0" euler="0 0 0" friction="2 0.02 0.01" />
                        <geom type="cylinder" size="0.0101 0.0251" mass=".01312" pos="0.053 0.0 0.0" euler="90 0 0" friction="2 0.02 0.01" />
                        <body name="right_big_toe" pos="0.053 0.0175 0.0">
                            <joint name="robot:right_big_toe" type="hinge" pos="0.0 0.0 0.0" axis="0 -1 0" range="-60 80" frictionloss=".002" armature=".0001" stiffness=".053" damping=".02" />
                            <site name="torque_right_big_toe" type="sphere" size="0.01" pos="0.0 0.0 0.0" group="4" />
                            <geom type="box" size="0.0095 0.007 0.0099" mass=".004425" pos="0.0095 0.0 0.0" euler="0 0 0" friction="2 0.02 0.01" />
                            <geom type="cylinder" size="0.01 0.0075" mass=".003934" pos="0.019 0.0 0.0" euler="90 0 0" friction="2 0.02 0.01" />
                        </body>
                        <body name="right_toes" pos="0.053 -0.0075 0.0">
                            <joint name="robot:right_toes" type="hinge" pos="0.0 0.0 0.0" axis="0 -1 0" range="-60 80" frictionloss=".002" armature=".0001" stiffness=".053" damping=".02" />
                            <site name="torque_right_toes" type="sphere" size="0.01" pos="0.0 0.0 0.0" group="4" />
                            <geom type="box" size="0.0095 0.016 0.0099" mass=".01006" pos="0.0095 0.0 0.0" euler="0 0 0" friction="2 0.02 0.01" />
                            <geom type="cylinder" size="0.01 0.0165" mass=".008612" pos="0.019 0.0 0.0" euler="90 0 0" friction="2 0.02 0.01" />
                        </body>
                </body>
            </body>
        </body>

        <body name="left_upper_leg" pos="0 0.03 0" euler="0 0 0">
            
            <joint name="robot:left_hip1" type="hinge" pos="0 0 0" axis="0 1 0" springref="-10" range="-133 20" stiffness="1.72" damping="1.27" frictionloss=".08" armature=".005" />
            <joint name="robot:left_hip2" type="hinge" pos="0 0 0" axis="-1 0 0" range="-51 17" stiffness="3.51" damping="1.99" frictionloss=".062" armature=".005" />
            <joint name="robot:left_hip3" type="hinge" pos="0 0 0" axis="0 0 1" range="-32 41" stiffness="2.16" damping="0.75" frictionloss=".027" armature=".005" />
            <site name="torque_left_hip" type="sphere" size="0.01" pos="0 0 0" group="4" />
            <geom name="left_uleg" type="capsule" material="pants_leg" contype="2" conaffinity="3" size="0.021500000000000002 0.045" mass=".8067" pos="0 0 -0.045" euler="0 0 0" />
            <body name="left_lower_leg" pos="0 0 -0.09">
                <joint name="robot:left_knee" type="hinge" pos="0 0 0" axis="0 -1 0" springref="-30" range="-145 4" stiffness="1.63" damping="0.53" frictionloss=".065" armature=".003" />
                <site name="torque_left_knee" type="sphere" size="0.01" pos="0 0 0" group="4" />
                <geom name="left_lleg" type="capsule" size="0.0183 0.032" mass=".3370" pos="0 0 -0.032" euler="0 0 0" />
                <body name="left_foot" pos="0 0 -0.0873">
                    <joint name="robot:left_foot1" type="hinge" pos="0.0 0.0 0.0" axis="0 -1 0" springref="-10" range="-63 32" stiffness="1.29" damping="0.6" frictionloss=".019" armature=".003" />
                        <joint name="robot:left_foot2" type="hinge" pos="0.0 0.0 0.0" axis="-1 0 0" range="-33 31" stiffness="0.96" damping="0.37" frictionloss=".011" armature=".0025" />
                        <joint name="robot:left_foot3" type="hinge" pos="0.0 0.0 0.0" axis="0 0 -1" range="-20 30" stiffness="1.15" damping="0.38" frictionloss=".012" armature=".002" />
                        <site name="torque_left_ankle" type="sphere" size="0.01" pos="0.0 0.0 0.0" group="4" />
                        <geom type="cylinder" size="0.0249 0.0101" mass=".03225" pos="-0.007 0.0 0.0" euler="0 0 0" />
                        <geom type="box" size="0.03 0.025 0.01" mass=".04923" pos="0.023 0.0 0.0" euler="0 0 0" friction="2 0.02 0.01" />
                        <geom type="cylinder" size="0.0101 0.0251" mass=".01312" pos="0.053 0.0 0.0" euler="90 0 0" friction="2 0.02 0.01" />
                        <body name="left_toes" pos="0.053 0.0075 0.0">
                            <joint name="robot:left_toes" type="hinge" pos="0.0 0.0 0.0" axis="0 -1 0" range="-60 80" frictionloss=".002" armature=".0001" stiffness=".053" damping=".02" />
                            <site name="torque_left_toes" type="sphere" size="0.01" pos="0.0 0.0 0.0" group="4" />
                            <geom type="box" size="0.0095 0.016 0.0099" mass=".01006" pos="0.0095 0.0 0.0" euler="0 0 0" friction="2 0.02 0.01" />
                            <geom type="cylinder" size="0.01 0.0165" mass=".008612" pos="0.019 0.0 0.0" euler="90 0 0" friction="2 0.02 0.01" />
                        </body>
                        <body name="left_big_toe" pos="0.053 -0.0175 0.0">
                            <joint name="robot:left_big_toe" type="hinge" pos="0.0 0.0 0.0" axis="0 -1 0" range="-60 80" frictionloss=".002" armature=".0001" stiffness=".053" damping=".02" />
                            <site name="torque_left_big_toe" type="sphere" size="0.01" pos="0.0 0.0 0.0" group="4" />
                            <geom type="box" size="0.0095 0.007 0.0099" mass=".004425" pos="0.0095 0.0 0.0" euler="0 0 0" friction="2 0.02 0.01" />
                            <geom type="cylinder" size="0.01 0.0075" mass=".003934" pos="0.019 0.0 0.0" euler="90 0 0" friction="2 0.02 0.01" />
                        </body>
                </body>
            </body>
        </body>
    </body>
</mujoco>