<mujoco model="MIMo">

	<body childclass="mimo" name="hip" pos="0 0 0">
		
		<geom name="lb" type="capsule" size="0.027389307207886213 0.024536254373731397 0.0" mass="0.21521769633101118" material="pants_down" pos="-0.002 0.0 0.002853052834154814" euler="90 0 0" />
		<site name="lowerBody_center" type="sphere" size=".01 .01 .01" pos="0 0 0" />
		<site name="BODY_25:MidHip" type="sphere" size=".005" pos="0.005 0.0 -0.007" rgba="0 0 0 1" />
		<body name="lower_body" pos="0.002 0.0 0.04336640307915317">
			<joint name="robot:hip_lean1" type="hinge" pos="0.0 0.0 -0.03024236004204103" axis="1 0 0" range="-14 14" stiffness="3.38" damping="0.77" frictionloss=".049" armature="0.01" />
			<joint name="robot:hip_rot1" type="hinge" pos="0.0 0.0 -0.03024236004204103" axis="0 0 1" range="-18 18" stiffness="1.45" damping="0.29" frictionloss=".018" armature="0.01" />
			<joint name="robot:hip_bend1" type="hinge" pos="0.0 0.0 -0.03024236004204103" axis="0 1 0" range="-17 30.5" stiffness="2.20" damping="0.84" frictionloss="0.040" armature="0.01" />
			<site name="torque_lb" type="sphere" size="0.01" pos="0 0 0" group="4" />
			<geom name="cb" type="capsule" size="0.03024236004204103 0.019971369839083698 0.0" mass="0.2460772089005735" material="pants_up" contype="0" pos="0.005 0.0 -0.004564884534647703" euler="90 0 0" />
			
			<body name="upper_body" pos="-0.002 0.0 0.05192556158161762">
				<joint name="robot:hip_lean2" type="hinge" pos="0 0 -.05" axis="1 0 0" range="-27 27" stiffness="1.69" damping="0.38" frictionloss=".024" armature="0.01" />
				<joint name="robot:hip_rot2" type="hinge" pos="0 0 -.05" axis="0 0 1" range="-18 18" stiffness="1.45" damping="0.29" frictionloss=".018" armature="0.01" />
				<joint name="robot:hip_bend2" type="hinge" pos="0 0 -.05" axis="0 1 0" range="-17 30.5" stiffness="2.20" damping="0.84" frictionloss="0.040" armature="0.01" />
				<site name="torque_ub" type="sphere" size="0.01" pos="0 0 0" group="4" />
				<geom name="ub1" type="capsule" size="0.029671749475210063 0.019971369839083694 0.0" mass="0.20217532557614493" material="top_down" pos="0.007 0.0 -0.018259538138590808" euler="90 0 0" />
				<geom name="ub2" type="capsule" size="0.027389307207886217 0.02225381210640754 0.0" mass="0.1764807404565155" material="top_middle" pos="0.004 0.0 0.017118317004928885" euler="90 0 0" />
				<geom name="ub3" type="capsule" size="0.023395033240069477 0.02681869664105525 0.0" mass="0.1340837460653408" material="top_up" pos="0.0 0.0 0.051354951014786654" euler="90 0 0" />
					
				<body name="head" pos="0.0 0.0 0.07474998425485613">
					<geom name="head" type="sphere" material="head" size="0.054080665096262276 0.0 0.0" mass="0.706990331884907" pos="0.007357913618539086 0.0 0.054080665096262276" />
					<site name="vestibular" type="sphere" size="0.01" pos="0.01 0 0.0735" group="4" />
					<site name="torque_neck" type="sphere" size="0.01" pos="0 0 0" group="4" />
					<joint name="robot:head_swivel" type="hinge" pos="0 0 0" axis="0 0 1" range="-111 111" stiffness=".23" damping=".29" frictionloss=".018" armature="0.005" />
					<joint name="robot:head_tilt" type="hinge" pos="0 0 0.0123" axis="0 1 0" range="-70 81" stiffness=".45" damping=".53" frictionloss=".018" armature="0.005" />
					<joint name="robot:head_tilt_side" type="hinge" pos="0 0 0.0245" axis="1 0 0" range="-70 70" stiffness=".37" damping=".29" frictionloss=".018" armature="0.005" />
                	<body name="left_eye" pos="0.05150539532977361 0.01802688836542076 0.04957394300490709">
						<site name="torque_left_eye" type="sphere" size="0.01" pos="0 0 0" group="4" />
						<joint name="robot:left_eye_horizontal" type="hinge" pos="0 0 0" axis="0 0 1" range="-45 45" stiffness=".00065" damping=".00042" frictionloss=".000054" armature=".0002" />
						<joint name="robot:left_eye_vertical" type="hinge" pos="0 0 0" axis="0 -1 0" range="-47 33" stiffness=".00065" damping=".00042" frictionloss=".000054" armature=".0002" />
						<joint name="robot:left_eye_torsional" type="hinge" pos="0 0 0" axis="-1 0 0" range="-8 8" stiffness=".00267" damping=".00042" frictionloss=".000037" armature=".0002" />
						<geom name="geom:left_eye1" type="sphere" material="eye_left" size="0.008277652820856471 0.0 0.0" mass="0.002499641837152238" pos="0 0 0" />
						<camera name="eye_left" mode="fixed" fovy="60" pos="0.01125 0 0" euler="90 -90 0" />
					</body>
					<body name="right_eye" pos="0.05150539532977361 -0.01802688836542076 0.04957394300490709">
						<site name="BODY_25:REye" type="sphere" size=".005 .005 .005" pos="0.0 0.0 0.0" rgba="0 0 0 1" />
						<site name="torque_right_eye" type="sphere" size="0.01" pos="0 0 0" group="4" />
						<joint name="robot:right_eye_horizontal" type="hinge" pos="0 0 0" axis="0 0 -1" range="-45 45" stiffness=".00065" damping=".00042" frictionloss=".000054" armature=".0002" />
						<joint name="robot:right_eye_vertical" type="hinge" pos="0 0 0" axis="0 -1 0" range="-47 33" stiffness=".00065" damping=".00042" frictionloss=".000054" armature=".0002" />
						<joint name="robot:right_eye_torsional" type="hinge" pos="0 0 0" axis="1 0 0" range="-8 8" stiffness=".00267" damping=".00042" frictionloss=".000037" armature=".0002" />
						<geom name="geom:right_eye1" type="sphere" material="eye_right" size="0.008277652820856471 0.0 0.0" mass="0.002499641837152238" pos="0 0 0" />
						<camera name="eye_right" mode="fixed" fovy="60" pos="0.01125 0 0" euler="90 -90 0" />
					</body>
				</body>
				<body name="right_upper_arm" pos="-0.005 -0.06523249634687195 0.05192556158161762" euler="170 0 0">
					
					<site name="BODY_25:RShoulder" type="sphere" size=".005 .005 .005" pos="0.0 0.0 0.0" rgba="0 0 0 1" />
					<joint name="robot:right_shoulder_horizontal" type="hinge" pos="0 0 0" axis="0 1 -4" range="-28 118" stiffness=".09" damping=".05" frictionloss=".0009" armature="0.004" />
					<joint name="robot:right_shoulder_ad_ab" type="hinge" pos="0 0 0" axis="-1 0 0" range="-84 183" stiffness=".11" damping=".10" frictionloss=".0014" armature="0.004" />
					<joint name="robot:right_shoulder_rotation" type="hinge" pos="0 0 0" axis="0 0 -1" range="-99 67" stiffness=".12" damping=".07" frictionloss=".0008" armature="0.004" />
					<site name="torque_right_shoulder" type="sphere" size="0.01" pos="0 0 0" group="4" />
					<geom name="right_uarm1" type="capsule" material="top_sleeve" size="0.015018766465747228 0.03929202947840549 0.0" mass="0.07445711976502113" pos="0.0 0.0 0.03929202947840549" euler="0 0 0" />
					<body name="right_lower_arm" pos="0.0 -0.0 0.07858405895681098" euler="0 0 0">
						<site name="BODY_25:RElbow" type="sphere" size=".005 .005 .005" pos="0.0 0.0 0.0" rgba="0 0 0 1" />
						<joint name="robot:right_elbow" type="hinge" pos="0 0 0" axis="0 -1 0" springref="-20" range="-146 5" stiffness=".13" damping=".11" frictionloss=".030" armature="0.002" />
						<site name="torque_right_elbow" type="sphere" size="0.01" pos="0 0 0" group="4" />
						<geom name="right_larm" type="capsule" size="0.014910209668292491 0.028568162949569202 0.0" mass="0.057301135481488394" pos="0.0 0.0 0.028568162949569202" />
						<body name="right_hand" pos="0.0 -0.0 0.06461905767388132" euler="0 0 0"> 
							<site name="BODY_25:RWrist" type="sphere" size=".005 .005 .005" pos="0.0 0.0 0.0" rgba="0 0 0 1" />
							<joint name="robot:right_hand1" type="hinge" pos="0 0 0" axis="0 0 -1" springref="-20" range="-90 90" stiffness=".22" damping=".03" frictionloss=".007" armature="0.001" />
							<joint name="robot:right_hand2" type="hinge" pos="0 0 0" axis="-1 0 0" range="-92 86" stiffness=".33" damping=".11" frictionloss=".007" armature="0.001" />
							<joint name="robot:right_hand3" type="hinge" pos="0 0 0" axis="0 1 0" range="-53 48" stiffness=".38" damping=".11" frictionloss=".007" armature="0.001" />
							<site name="torque_right_wrist" type="sphere" size="0.01" pos="0 0 0" group="4" />
							<geom name="geom:right_hand1" type="box" size="0.020018572295820818 0.007174866251031315 0.014304608113573057" mass="0.015168199081090732" pos="0.0035874331255156574 0.0 0.014304608113573057" />
							<geom name="geom:right_hand2" type="cylinder" size="0.0073748662510313145 0.020018572295820818 0.0" mass="0.006030575653019663" pos="0.0035874331255156574 0.0 0.028609216227146114" euler="0 90 0" />
							<body name="right_fingers" pos="0.0 -0.0 0.028609216227146114"> 
								<joint name="robot:right_fingers" type="hinge" pos="0 0 0" axis="-1 0 0" springref="-40" range="-160 8" stiffness=".017" damping=".018" frictionloss=".0023" armature="0.0001" />
								<site name="torque_right_fingers" type="sphere" size="0.01" pos="0 0 0" group="4" />
								<geom name="geom:right_fingers1" type="box" size="0.017686268652304795 0.007174866251031315 0.01423583595918088" mass="0.013373673318932218" pos="0.0 0.0 0.01423583595918088" friction="5 0.02 0.01" />
								<geom name="geom:right_fingers2" type="cylinder" size="0.0073748662510313145 0.017886268652304794 0.0" mass="0.005378481896058459" pos="0.0 0.0 0.02847167191836176" euler="0 90 0" friction="5 0.02 0.01" />
							</body>
						</body>
					</body>
				</body>
				
				<body name="left_upper_arm" pos="-0.005 0.06523249634687195 0.05192556158161762" euler="-170 0 0">
					
					<site name="BODY_25:LShoulder" type="sphere" size=".005 .005 .005" pos="0.0 0.0 0.0" rgba="0 0 0 1" />
					<joint name="robot:left_shoulder_horizontal" type="hinge" pos="0 0 0" axis="0 1 4" range="-28 118" stiffness=".09" damping=".05" frictionloss=".0009" armature="0.004" />
					<joint name="robot:left_shoulder_ad_ab" type="hinge" pos="0 0 0" axis="1 0 0" range="-84 183" stiffness=".11" damping=".10" frictionloss=".0014" armature="0.004" />
					<joint name="robot:left_shoulder_rotation" type="hinge" pos="0 0 0" axis="0 0 1" range="-99 67" stiffness=".12" damping=".07" frictionloss=".0008" armature="0.004" />
					<site name="torque_left_shoulder" type="sphere" size="0.01" pos="0 0 0" group="4" />
					<geom name="left_uarm1" type="capsule" material="top_sleeve" size="0.015018766465747228 0.03929202947840549 0.0" mass="0.07445711976502113" pos="0.0 0.0 0.03929202947840549" euler="0 0 0" />
					<body name="left_lower_arm" pos="0.0 0.0 0.07858405895681098" euler="0 0 0">
						<site name="BODY_25:LElbow" type="sphere" size=".005 .005 .005" pos="0.0 0.0 0.0" rgba="0 0 0 1" />
						<joint name="robot:left_elbow" type="hinge" pos="0 0 0" axis="0 -1 0" springref="-20" range="-146 5" stiffness=".13" damping=".11" frictionloss=".030" armature="0.002" />
						<site name="torque_left_elbow" type="sphere" size="0.01" pos="0 0 0" group="4" />
						<geom name="left_larm" type="capsule" size="0.014910209668292491 0.028568162949569202 0.0" mass="0.057301135481488394" pos="0.0 0.0 0.028568162949569202" />
						<body name="left_hand" pos="0.0 0.0 0.06461905767388132" euler="0 0 0"> 
							<site name="BODY_25:LWrist" type="sphere" size=".005 .005 .005" pos="0.0 0.0 0.0" rgba="0 0 0 1" />
							<joint name="robot:left_hand1" type="hinge" pos="0 0 0" axis="0 0 1" springref="-20" range="-90 90" stiffness=".22" damping=".03" frictionloss=".007" armature="0.001" />
							<joint name="robot:left_hand2" type="hinge" pos="0 0 0" axis="1 0 0" range="-92 86" stiffness=".33" damping=".11" frictionloss=".007" armature="0.001" />
							<joint name="robot:left_hand3" type="hinge" pos="0 0 0" axis="0 1 0" range="-53 48" stiffness=".38" damping=".11" frictionloss=".007" armature="0.001" />
							<site name="torque_left_wrist" type="sphere" size="0.01" pos="0 0 0" group="4" />
							<geom name="geom:left_hand1" type="box" size="0.020018572295820818 0.007174866251031315 0.014304608113573057" mass="0.015168199081090732" pos="0.0035874331255156574 0.0 0.014304608113573057" />
							<geom name="geom:left_hand2" type="cylinder" size="0.0073748662510313145 0.020018572295820818 0.0" mass="0.006030575653019663" pos="0.0035874331255156574 0.0 0.028609216227146114" euler="0 90 0" />
							<body name="left_fingers" pos="0.0 0.0 0.028609216227146114"> 
								<joint name="robot:left_fingers" type="hinge" pos="0 0 0" axis="1 0 0" springref="-40" range="-160 8" stiffness=".017" damping=".018" frictionloss=".0023" armature="0.0001" />
								<site name="torque_left_fingers" type="sphere" size="0.01" pos="0 0 0" group="4" />
								<geom name="geom:left_fingers1" type="box" size="0.017686268652304795 0.007174866251031315 0.01423583595918088" mass="0.013373673318932218" pos="0.0 0.0 0.01423583595918088" friction="5 0.02 0.01" />
								<geom name="geom:left_fingers2" type="cylinder" size="0.0073748662510313145 0.017886268652304794 0.0" mass="0.005378481896058459" pos="0.0 0.0 0.02847167191836176" euler="0 90 0" friction="5 0.02 0.01" />
							</body>
						</body>
					</body>
				</body>
			</body>
		</body>
			
		<body name="right_upper_leg" pos="0.005 -0.0291011389083791 -0.007">
			
			<joint name="robot:right_hip1" type="hinge" pos="0 0 0" axis="0 1 0" springref="-10" range="-133 20" stiffness="1.72" damping="1.27" frictionloss=".08" armature=".005" />
			<joint name="robot:right_hip2" type="hinge" pos="0 0 0" axis="1 0 0" range="-51 17" stiffness="3.51" damping="1.99" frictionloss=".062" armature=".005" />
			<joint name="robot:right_hip3" type="hinge" pos="0 0 0" axis="0 0 -1" range="-32 41" stiffness="2.16" damping="0.75" frictionloss=".027" armature=".005" />
			<site name="torque_right_hip" type="sphere" size="0.01" pos="0 0 0" group="4" />
			<site name="BODY_25:RHip" type="sphere" size=".005 .005 .005" pos="0.0 0.0 0.0" rgba="0 0 0 1" />
			<geom name="geom:right_upper_leg1" type="capsule" material="pants_leg" contype="2" conaffinity="3" size="0.026090365627520182 0.040153927118548885 0.0" mass="0.2625513992010872" pos="0.0 0.0 -0.04143885278634245" euler="0 0 0" />
			<body name="right_lower_leg" pos="0.0 -0.0 -0.09233465837358926">
				<joint name="robot:right_knee" type="hinge" pos="0 0 0" axis="0 -1 0" springref="-30" range="-145 4" stiffness="1.63" damping="0.53" frictionloss=".065" armature=".003" />
				<site name="torque_right_knee" type="sphere" size="0.01" pos="0 0 0" group="4" />
				<site name="BODY_25:RKnee" type="sphere" size=".005 .005 .005" pos="0.0 0.0 0.0" rgba="0 0 0 1" />
				<geom name="geom:right_lower_leg1" type="capsule" size="0.01900339384896901 0.030034866290255584 0.0" mass="0.09673351056966385" pos="0.0 0.0 -0.030034866290255584" euler="0 0 0" />
				<geom name="geom:right_lower_leg2" type="capsule" size="0.014526774092090683 0.01911309673016265 0.0" mass="0.03805966514099927" pos="0.0 0.0 -0.09010459887076674" euler="0 0 0" />
				<body name="right_foot" pos="0.0 -0.0 -0.12013946516102234">
					<joint name="robot:right_foot1" type="hinge" pos="0.0 -0.0 0.010337227855299266" axis="0 -1 0" springref="-10" range="-63 32" stiffness="1.29" damping="0.6" frictionloss=".019" armature=".003" />
					<joint name="robot:right_foot2" type="hinge" pos="0.0 -0.0 0.010337227855299266" axis="1 0 0" range="-33 31" stiffness="0.96" damping="0.37" frictionloss=".011" armature=".0025" />
					<joint name="robot:right_foot3" type="hinge" pos="0.0 -0.0 0.010337227855299266" axis="0 0 1" range="-20 30" stiffness="1.15" damping="0.38" frictionloss=".012" armature=".002" />
					<site name="torque_right_ankle" type="sphere" size="0.01" pos="0 0 0" group="4" />
					<site name="BODY_25:RAnkle" type="sphere" size=".005" pos="0.0 0.0 0.010337227855299266" rgba="0 0 0 1" />
					<site name="BODY_25:RHeel" type="sphere" size=".005" pos="-0.023709606392309245 0.0 0.0" rgba="0 0 0 1" />
					<geom name="geom:right_foot1" type="cylinder" size="0.017826719384593483 0.006791485236866177 0.0" mass="0.011318651942872357" pos="-0.010838677207912798 0.0 0.0" euler="0 0 0" />
					<geom name="geom:right_foot2" type="box" size="0.023709606392309245 0.017926719384593483 0.006891485236866177" mass="0.019583296877112293" pos="0.01287092918439645 0.0 0.0" euler="0 0 0" friction="2 0.02 0.01" />
					<geom name="geom:right_foot3" type="cylinder" size="0.006791485236866177 0.017726719384593484 0.0" mass="0.004265353944485406" pos="0.036580535576705694 0.0 0.0" euler="90 0 0" friction="2 0.02 0.01" />
					<body name="right_toes" pos="0.036580535576705694 -0.0 0.0">
						<joint name="robot:right_toes" type="hinge" pos="0 0 0" axis="0 -1 0" range="-60 80" frictionloss=".005" armature=".0005" stiffness=".106" damping=".04" />
						<site name="torque_right_toes" type="sphere" size="0.01" pos="0 0 0" group="4" />
						<geom name="geom:right_toes1" type="box" size="0.004741921278461849 0.017826719384593483 0.006791485236866177" mass="0.0036065107376409386" pos="0.004741921278461849 0.0 0.0" euler="0 0 0" friction="2 0.02 0.01" />
						<geom name="geom:right_toes2" type="cylinder" size="0.006891485236866177 0.017926719384593483 0.0" mass="0.004175196714455051" pos="0.009483842556923697 0.0 0.0" euler="90 0 0" friction="2 0.02 0.01" />
						<site name="BODY_25:RBigToe" type="sphere" size=".005" pos="0.007451590580440047 0.00860482530460487 0.0" rgba="0 0 0 1" />
						<site name="BODY_25:RSmallToe" type="sphere" size=".005" pos="0.006774173254945498 -0.00860482530460487 0.0" rgba="0 0 0 1" />
					</body>
				</body>
			</body>
		</body>
			
		<body name="left_upper_leg" pos="0.005 0.0291011389083791 -0.007">
			
			<site name="BODY_25:LHip" type="sphere" size=".005 .005 .005" pos="0.0 0.0 0.0" rgba="0 0 0 1" />
			<joint name="robot:left_hip1" type="hinge" pos="0 0 0" axis="0 1 0" springref="-10" range="-133 20" stiffness="1.72" damping="1.27" frictionloss=".08" armature=".005" />
			<joint name="robot:left_hip2" type="hinge" pos="0 0 0" axis="-1 0 0" range="-51 17" stiffness="3.51" damping="1.99" frictionloss=".062" armature=".005" />
			<joint name="robot:left_hip3" type="hinge" pos="0 0 0" axis="0 0 1" range="-32 41" stiffness="2.16" damping="0.75" frictionloss=".027" armature=".005" />
			<site name="torque_left_hip" type="sphere" size="0.01" pos="0 0 0" group="4" />
			<geom name="geom:left_upper_leg1" type="capsule" material="pants_leg" contype="2" conaffinity="3" size="0.026090365627520182 0.040153927118548885 0.0" mass="0.2625513992010872" pos="0.0 0.0 -0.04143885278634245" euler="0 0 0" />
			<body name="left_lower_leg" pos="0.0 0.0 -0.09233465837358926">
				<joint name="robot:left_knee" type="hinge" pos="0 0 0" axis="0 -1 0" springref="-30" range="-145 4" stiffness="1.63" damping="0.53" frictionloss=".065" armature=".003" />
				<site name="torque_left_knee" type="sphere" size="0.01" pos="0 0 0" group="4" />
				<site name="BODY_25:LKnee" type="sphere" size=".005" pos="0.0 0.0 0.0" rgba="0 0 0 1" />
				<geom name="geom:left_lower_leg1" type="capsule" size="0.01900339384896901 0.030034866290255584 0.0" mass="0.09673351056966385" pos="0.0 0.0 -0.030034866290255584" euler="0 0 0" />
				<geom name="geom:left_lower_leg2" type="capsule" size="0.014526774092090683 0.01911309673016265 0.0" mass="0.03805966514099927" pos="0.0 0.0 -0.09010459887076674" euler="0 0 0" />
				<body name="left_foot" pos="0.0 0.0 -0.12013946516102234">
					<joint name="robot:left_foot1" type="hinge" pos="0.0 0.0 0.010337227855299266" axis="0 -1 0" springref="-10" range="-63 32" stiffness="1.29" damping="0.6" frictionloss=".019" armature=".003" />
					<joint name="robot:left_foot2" type="hinge" pos="0.0 0.0 0.010337227855299266" axis="-1 0 0" range="-33 31" stiffness="0.96" damping="0.37" frictionloss=".011" armature=".0025" />
					<joint name="robot:left_foot3" type="hinge" pos="0.0 0.0 0.010337227855299266" axis="0 0 -1" range="-20 30" stiffness="1.15" damping="0.38" frictionloss=".012" armature=".002" />
					<site name="torque_left_ankle" type="sphere" size="0.01" pos="0 0 0" group="4" />
					<site name="BODY_25:LAnkle" type="sphere" size=".005" pos="0.0 0.0 0.010337227855299266" rgba="0 0 0 1" />
					<site name="BODY_25:LHeel" type="sphere" size=".005" pos="-0.023709606392309245 0.0 0.0" rgba="0 0 0 1" />
					<geom name="geom:left_foot1" type="cylinder" size="0.017826719384593483 0.006791485236866177 0.0" mass="0.011318651942872357" pos="-0.010838677207912798 0.0 0.0" euler="0 0 0" />
					<geom name="geom:left_foot2" type="box" size="0.023709606392309245 0.017926719384593483 0.006891485236866177" mass="0.019583296877112293" pos="0.01287092918439645 0.0 0.0" euler="0 0 0" friction="2 0.02 0.01" />
					<geom name="geom:left_foot3" type="cylinder" size="0.006791485236866177 0.017726719384593484 0.0" mass="0.004265353944485406" pos="0.036580535576705694 0.0 0.0" euler="90 0 0" friction="2 0.02 0.01" />
					<body name="left_toes" pos="0.036580535576705694 0.0 0.0">
						<joint name="robot:left_toes" type="hinge" pos="0 0 0" axis="0 -1 0" range="-60 80" frictionloss=".005" armature=".0005" stiffness=".106" damping=".04" />
						<site name="torque_left_toes" type="sphere" size="0.01" pos="0 0 0" group="4" />
						<geom name="geom:left_toes1" type="box" size="0.004741921278461849 0.017826719384593483 0.006791485236866177" mass="0.0036065107376409386" pos="0.004741921278461849 0.0 0.0" euler="0 0 0" friction="2 0.02 0.01" />
						<geom name="geom:left_toes2" type="cylinder" size="0.006891485236866177 0.017926719384593483 0.0" mass="0.004175196714455051" pos="0.009483842556923697 0.0 0.0" euler="90 0 0" friction="2 0.02 0.01" />
						<site name="BODY_25:LBigToe" type="sphere" size=".005" pos="0.007451590580440047 -0.00860482530460487 0.0" rgba="0 0 0 1" />
						<site name="BODY_25:LSmallToe" type="sphere" size=".005" pos="0.006774173254945498 0.00860482530460487 0.0" rgba="0 0 0 1" />
					</body>
				</body>
			</body>
		</body>
		
	</body>

</mujoco>
